Workbook

Sheet Prod vol-Ship
D1: Start date | E1: 46204
B2: Prod Vol (Output-KP) | D2: Today | E2: =TODAY() -> 46248 | F2: =DAY(E2-E1) -> 13
B3: Process | C3: Series/Case | D3: Jul'26 Target | E3: Daily Goal | F3: MTD Goal | G3: MTD | H3: Pace | I3: Performance MTD
A4: TaPoly | B4: TET's anode | C4: All | D4: 28964 | E4: 965.46667 | F4: 9654.6667 | G4: 12733 | H4: =G4-F4 -> 3078.3333 | I4: =G4/F4 -> 1.3188441
B5: Racking | C5: All | D5: 176522.52 | E5: 5884.084 | F5: 58840.84 | G5: 74100.9 | H5: =G5-F5 -> 15260.06 | I5: =G5/F5 -> 1.2593447
B6: BOL (Silver) | C6: PSLA | D6: 9552.2867 | E6: 318.40956 | F6: 3184.0956 | G6: 3828.401 | H6: =G6-F6 -> 644.30545 | I6: =G6/F6 -> 1.2023512
C7: PSLB | D7: 132957.06 | E7: 4431.9018 | F7: 44319.018 | G7: 54800.263 | H7: =G7-F7 -> 10481.245 | I7: =G7/F7 -> 1.2364954
C8: FPSA | D8: 18639.959 | E8: 621.33198 | F8: 6213.3198 | G8: 9114.193 | H8: =G8-F8 -> 2900.8732 | I8: =G8/F8 -> 1.4668797
C9: FPSB | D9: 10361.348 | E9: 345.37828 | F9: 3453.7828 | G9: 4438.272 | H9: =G9-F9 -> 984.48917 | I9: =G9/F9 -> 1.2850466
C10: GPSP2 | D10: 3963.1937 | E10: 132.10646 | F10: 1321.0646 | G10: 1726.75 | H10: =G10-F10 -> 405.68544 | I10: =G10/F10 -> 1.3070898
C11: Total | D11: 175473.84 | E11: 5849.1281 | F11: 58491.281 | G11: 73907.879 | H11: =SUM(H6:H10) -> 15416.598 | I11: =G11/F11 -> 1.2635709
B12: EOL (E/I) | C12: PSLA | D12: 8600 | E12: 286.66667 | F12: 2866.6667 | G12: 3818 | H12: =G12-F12 -> 951.33333 | I12: =G12/F12 -> 1.3318605
C13: PSLB | D13: 120794.95 | E13: 4026.4983 | F13: 40264.983 | G13: 51107 | H13: =G13-F13 -> 10842.017 | I13: =G13/F13 -> 1.2692666
C14: FPSA | D14: 15200 | E14: 506.66667 | F14: 5066.6667 | G14: 5775 | H14: =G14-F14 -> 708.33333 | I14: =G14/F14 -> 1.1398026
C15: FPSB | D15: 8900 | E15: 296.66667 | F15: 2966.6667 | G15: 4224 | H15: =G15-F15 -> 1257.3333 | I15: =G15/F15 -> 1.4238202
C16: GPSP2 | D16: 3200 | E16: 106.66667 | F16: 1066.6667 | G16: 1323 | H16: =G16-F16 -> 256.33333 | I16: =G16/F16 -> 1.2403125
C17: Total | D17: 156694.95 | E17: 5223.165 | F17: 52231.65 | G17: 66247 | H17: =SUM(H12:H16) -> 14015.35 | I17: =G17/F17 -> 1.2683306
B18: Final (901) | C18: PSLA | D18: 8600 | E18: =D18/30 -> 286.66667 | F18: =E18*$F$2 -> 3726.6667 | G18: =SUM('[1]Output_Jul''26'!$Q$49) -> 3886 | H18: =G18-F18 -> 159.33333 | I18: =G18/F18 -> 1.0427549
C19: PSLB | D19: 120000 | E19: =D19/30 -> 4000 | F19: =E19*$F$2 -> 52000 | G19: =SUM('[1]Output_Jul''26'!$Q$50:$Q$55) -> 51374 | H19: =G19-F19 -> -626 | I19: =G19/F19 -> 0.98796154
C20: FPSA | D20: 15200 | E20: =D20/30 -> 506.66667 | F20: =E20*$F$2 -> 6586.6667 | G20: =SUM('[1]Output_Jul''26'!$Q$56:$Q$59,'[1]Output_Jul''26'!$Q$63) -> 4956 | H20: =G20-F20 -> -1630.6667 | I20: =G20/F20 -> 0.75242915
C21: FPSB | D21: 8900 | E21: =D21/30 -> 296.66667 | F21: =E21*$F$2 -> 3856.6667 | G21: =SUM('[1]Output_Jul''26'!$Q$60:$Q$61) -> 4005 | H21: =G21-F21 -> 148.33333 | I21: =G21/F21 -> 1.0384615
C22: GPSP2 | D22: 3200 | E22: =D22/30 -> 106.66667 | F22: =E22*$F$2 -> 1386.6667 | G22: ='[1]Output_Jul''26'!$Q$62 -> 1140 | H22: =G22-F22 -> -246.66667 | I22: =G22/F22 -> 0.82211538
C23: Total | D23: =SUM(D18:D22) -> 155900 | E23: =SUM(E18:E22) -> 5196.6667 | F23: =SUM(F18:F22) -> 67556.667 | G23: =SUM(G18:G22) -> 65361 | H23: =G23-F23 -> -2195.6667 | I23: =G23/F23 -> 0.96749889
A24: SC | B24: Can | D24: 800 | E24: =D24/30 -> 26.666667 | F24: =E24*$F$2 -> 346.66667 | G24: 437.258 | H24: =G24-F24 -> 90.591333 | I24: =G24/F24 -> 1.2613212
B25: FC | D25: 1550.0003 | E25: =D25/30 -> 51.666678 | F25: =E25*$F$2 -> 671.66682 | G25: 838 | H25: =G25-F25 -> 166.33318 | I25: =G25/F25 -> 1.2476424
B26: FM | D26: 1200 | E26: =D26/30 -> 40 | F26: =E26*$F$2 -> 520 | G26: 792.2 | H26: =G26-F26 -> 272.2 | I26: =G26/F26 -> 1.5234615
B27: TTL FG | D27: =SUM(D24:D26) -> 3550.0003 | E27: =D27/30 -> 118.33334 | F27: =E27*$F$2 -> 1538.3335 | G27: =SUM(G24:G26) -> 2067.458 | H27: =G27-F27 -> 529.12452 | I27: =G27/F27 -> 1.3439596
B31: Shipping (KP)
C32: Series/Case | D32: Jul'26 Target | E32: Daily Goal | F32: MTD Goal | G32: MTD | H32: Pace | I32: Performance MTD
A33: TaPoly | C33: PSL+PSG | D33: 113208 | F33: =SUM('[1]Ship_Jul''26'!$D$4:$Q$4) -> 30112 | G33: =SUM('[1]Ship_Jul''26'!$D$9:$Q$9) -> 35935 | H33: =G33-F33 -> 5823 | I33: =G33/F33 -> 1.1933781
C34: FPS+FPU | D34: 18057 | F34: =SUM('[1]Ship_Jul''26'!$D$5:$Q$5) -> 7959 | G34: =SUM('[1]Ship_Jul''26'!$D$10:$Q$10) -> 8130 | H34: =G34-F34 -> 171 | I34: =G34/F34 -> 1.0214851
C35: GPS | D35: 3138 | F35: =SUM('[1]Ship_Jul''26'!$D$6:$Q$6) -> 1158 | G35: =SUM('[1]Ship_Jul''26'!$D$11:$Q$11) -> 1266 | H35: =G35-F35 -> 108 | I35: =G35/F35 -> 1.0932642
C36: TTL | D36: =SUM(D33:D35) -> 134403 | F36: =SUM(F33:F35) -> 39229 | G36: =SUM(G33:G35) -> 45331 | H36: =G36-F36 -> 6102 | I36: =G36/F36 -> 1.1555482
A37: SC | C37: Can | D37: 797.63 | F37: =SUM('[1]Ship_Jul''26'!$D$16:$Q$16) -> 337.26 | G37: ='[1]Ship_Jul''26'!$C$21 -> 470.66 | H37: =G37-F37 -> 133.4 | I37: =G37/F37 -> 1.3955405
C38: FC | D38: 1552.4 | F38: =SUM('[1]Ship_Jul''26'!$D$17:$Q$17) -> 256.15 | G38: ='[1]Ship_Jul''26'!$C$22 -> 531.8 | H38: =G38-F38 -> 275.65 | I38: =G38/F38 -> 2.0761273
C39: FM | D39: 1185.3 | F39: =SUM('[1]Ship_Jul''26'!$D$18:$Q$18) -> 671 | G39: ='[1]Ship_Jul''26'!$C$23 -> 1006 | H39: =G39-F39 -> 335 | I39: =G39/F39 -> 1.4992548
C40: TTL | D40: =SUM(D37:D39) -> 3535.33 | F40: =SUM(F37:F39) -> 1264.41 | G40: =SUM(G37:G39) -> 2008.46 | H40: =G40-F40 -> 744.05 | I40: =G40/F40 -> 1.5884563

Sheet Daily_Yield_Ta
A1: =TODAY()-1 -> 46247 | AQ1: Today
D2: Target (Aug'26) | G2: 46235 | J2: 46236 | M2: 46237 | P2: 46238 | S2: 46239 | V2: 46240 | Y2: 46241 | AB2: 46242 | AE2: 46243 | AH2: 46244 | AK2: 46245 | AN2: 46246 | AQ2: 46247 | AT2: 46248 | AW2: 46249 | AZ2: 46250 | BC2: 46252 | BF2: 46252 | BI2: 46253 | BL2: 46254 | BO2: 46255 | BR2: 46256 | BU2: 46257 | BX2: 46258 | CA2: 46259 | CD2: 46260 | CG2: 46262 | CJ2: 46262 | CM2: 46263 | CP2: 46264 | CS2: 46265 | CV2: MTD
B3: Sub | C3: Case | D3: %Yield | E3: Output (KP) | F3: Lot | G3: %Yield | H3: Output (KP) | I3: Lot | J3: %Yield | K3: Output (KP) | L3: Lot | M3: %Yield | N3: Output (KP) | O3: Lot | P3: %Yield | Q3: Output (KP) | R3: Lot | S3: %Yield | T3: Output (KP) | U3: Lot | V3: %Yield | W3: Output (KP) | X3: Lot | Y3: %Yield | Z3: Output (KP) | AA3: Lot | AB3: %Yield | AC3: Output (KP) | AD3: Lot | AE3: %Yield | AF3: Output (KP) | AG3: Lot | AH3: %Yield | AI3: Output (KP) | AJ3: Lot | AK3: %Yield | AL3: Output (KP) | AM3: Lot | AN3: %Yield | AO3: Output (KP) | AP3: Lot | AQ3: %Yield | AR3: Output (KP) | AS3: Lot | AT3: %Yield | AU3: Output (KP) | AV3: Lot | AW3: %Yield | AX3: Output (KP) | AY3: Lot | AZ3: %Yield | BA3: Output (KP) | BB3: Lot | BC3: %Yield | BD3: Output (KP) | BE3: Lot | BF3: %Yield | BG3: Output (KP) | BH3: Lot | BI3: %Yield | BJ3: Output (KP) | BK3: Lot | BL3: %Yield | BM3: Output (KP) | BN3: Lot | BO3: %Yield | BP3: Output (KP) | BQ3: Lot | BR3: %Yield | BS3: Output (KP) | BT3: Lot | BU3: %Yield | BV3: Output (KP) | BW3: Lot | BX3: %Yield | BY3: Output (KP) | BZ3: Lot | CA3: %Yield | CB3: Output (KP) | CC3: Lot | CD3: %Yield | CE3: Output (KP) | CF3: Lot | CG3: %Yield | CH3: Output (KP) | CI3: Lot | CJ3: %Yield | CK3: Output (KP) | CL3: Lot | CM3: %Yield | CN3: Output (KP) | CO3: Lot | CP3: %Yield | CQ3: Output (KP) | CR3: Lot | CS3: %Yield | CT3: Output (KP) | CU3: Lot | CV3: %Yield | CW3: Output (KP) | CX3: Lot | CY3: Diff with Target
A4: TaPoly | B4: FPS | C4: A3 | D4: 92.8 | E4: 5100 | F4: 320 | G4: 92.112187 | H4: 175.05 | I4: 10 | J4: 87.368226 | K4: 249.874 | L4: 15 | M4: 87.33 | N4: 227.381 | O4: 12 | P4: 89.09 | Q4: 284.504 | R4: 15 | S4: 85.68 | T4: 248.552 | U4: 13 | V4: 87.38 | W4: 285.333 | X4: 15 | Y4: 87.19 | Z4: 229.841 | AA4: 12 | AB4: 91.68 | AC4: 266.28 | AD4: 14 | AE4: 89.85 | AF4: 247.309 | AG4: 13 | AH4: 88.34 | AI4: 247.41 | AJ4: 13 | AK4: 89.89 | AL4: 228.223 | AM4: 12 | AN4: 89.25 | AO4: 248.109 | AP4: 13 | CV4: 88.7 | CW4: =+H4+K4+N4+Q4+T4+W4+Z4+AC4+AF4+AI4+AL4+AO4 -> 2937.866 | CX4: =I4+L4+O4+R4+U4+X4+AD4+AG4+AJ4+AM4+AP4 -> 145 | CY4: =CV4-D4 -> -4.1
A5: (E/I) | B5: FPS | C5: A2 | D5: 93.6 | E5: 2400 | F5: 140.2741 | G5: 94.660014 | H5: 89.165 | I5: 5 | J5: 92.533728 | K5: 105.147 | L5: 6 | M5: 94.96 | N5: 76.205 | O5: 4 | P5: 94.22 | Q5: 75.766 | R5: 4 | S5: 93.42 | T5: 112.52 | U5: 6 | V5: 90.78 | W5: 95.24 | X5: 5 | Y5: 94.46 | Z5: 76.491 | AA5: 4 | AB5: 94.54 | AC5: 133.36 | AD5: 7 | AE5: 93.39 | AF5: 151.139 | AG5: 8 | AH5: 94.01 | AI5: 75.517 | AJ5: 4 | AK5: 94.13 | AL5: 132.622 | AM5: 7 | AN5: 94.52 | AO5: 75.352 | AP5: 4 | CV5: 93.75 | CW5: =+H5+K5+N5+Q5+T5+W5+Z5+AC5+AF5+AI5+AL5+AO5 -> 1198.524 | CX5: =I5+L5+O5+R5+U5+X5+AD5+AG5+AJ5+AM5+AP5 -> 60 | CY5: =CV5-D5 -> 0.15
B6: FPS | C6: B3 | D6: 90 | E6: 7500 | F6: 850 | G6: 93.600954 | H6: 277.89 | I6: 26 | J6: 94.576957 | K6: 235.647 | L6: 22 | M6: 94.13 | N6: 237.08 | O6: 21 | P6: 94.45 | Q6: 282.624 | R6: 25 | S6: 93.86 | T6: 328.879 | U6: 29 | V6: 93.26 | W6: 306.844 | X6: 27 | Y6: 92.68 | Z6: 272.08 | AA6: 24 | AB6: 93.05 | AC6: 288.336 | AD6: 26 | AE6: 94.01 | AF6: 328.799 | AG6: 29 | AH6: 92.5 | AI6: 267.8 | AJ6: 24 | AK6: 93.21 | AL6: 273.926 | AM6: 24 | AN6: 93.63 | AO6: 271.575 | AP6: 24 | CV6: 93.57 | CW6: =+H6+K6+N6+Q6+T6+W6+Z6+AC6+AF6+AI6+AL6+AO6 -> 3371.48 | CX6: =I6+L6+O6+R6+U6+X6+AD6+AG6+AJ6+AM6+AP6 -> 277 | CY6: =CV6-D6 -> 3.57
B7: FPS | C7: B10 | D7: 92 | E7: 0 | F7: 0
B8: FPS | C8: A08 | D8: 79 | E8: 6000 | F8: 399 | G8: 89.270073 | H8: 237.262 | I8: 14 | J8: 86.866117 | K8: 246.857 | L8: 15 | M8: 88.07 | N8: 302.512 | O8: 16 | P8: 88.39 | Q8: 321.496 | R8: 17 | S8: 85.95 | T8: 303.392 | U8: 16 | V8: 86.08 | W8: 225.712 | X8: 12 | Y8: 88.31 | Z8: 304.251 | AA8: 16 | AB8: 88.26 | AC8: 266.823 | AD8: 14 | AE8: 89.11 | AF8: 282.78 | AG8: 15 | AH8: 85.85 | AI8: 303.518 | AJ8: 16 | AK8: 89.26 | AL8: 264.878 | AM8: 14 | AN8: 87.25 | AO8: 303 | AP8: 16 | CV8: 87.73 | CW8: =+H8+K8+N8+Q8+T8+W8+Z8+AC8+AF8+AI8+AL8+AO8 -> 3362.481 | CX8: =I8+L8+O8+R8+U8+X8+AD8+AG8+AJ8+AM8+AP8 -> 165 | CY8: =CV8-D8 -> 8.73
B9: FPU | C9: A2 | D9: 93.6 | E9: 0 | F9: 0 | W9: 0
B10: FACE DOWN | C10: Total | D10: 89.460719 | E10: =SUM(E4:E9) -> 21000 | F10: =SUM(F4:F9) -> 1709.2741 | G10: 92.025533 | H10: 779.367 | I10: 55 | J10: 89.769575 | K10: 837.525 | L10: 58 | M10: 90.19 | N10: 843.178 | O10: 53 | P10: 90.83 | Q10: 964.39 | R10: 61 | S10: 89.35 | T10: 993.343 | U10: 64 | V10: 89.39 | W10: 913.129 | X10: 59 | Y10: 89.9 | Z10: 882.663 | AA10: 56 | AB10: 91.54 | AC10: 954.799 | AD10: 61 | AE10: 91.53 | AF10: 1010.027 | AG10: 65 | AH10: 89.22 | AI10: 894.245 | AJ10: 57 | AK10: 91.34 | AL10: 899.649 | AM10: 57 | AN10: 90.34 | AO10: 898.036 | AP10: 57 | CV10: 90.46 | CW10: =+H10+K10+N10+Q10+T10+W10+Z10+AC10+AF10+AI10+AL10+AO10 -> 10870.351 | CX10: =I10+L10+O10+R10+U10+X10+AD10+AG10+AJ10+AM10+AP10 -> 647 | CY10: =CV10-D10 -> 0.99928068
B11: GPS | C11: P2 | D11: 84.2 | E11: 3400 | F11: 186 | G11: 82.61917 | H11: 85.396 | I11: 4 | J11: 83.761554 | K11: 106.115 | L11: 5 | M11: 87.48 | N11: 127.309 | O11: 5 | P11: 69.36 | Q11: 50.223 | R11: 2 | S11: 82.88 | T11: 101.957 | U11: 4 | V11: 86.53 | W11: 154.495 | X11: 6 | Y11: 84.64 | Z11: 103.418 | AA11: 4 | AB11: 77.91 | AC11: 102.977 | AD11: 4 | AE11: 76.08 | AF11: 103.567 | AG11: 4 | AH11: 78.74 | AI11: 166.269 | AJ11: 7 | AK11: 85.36 | AL11: 153.569 | AM11: 6 | AN11: 78.01 | AO11: 74.336 | AP11: 3 | CV11: 82.05 | CW11: =+H11+K11+N11+Q11+T11+W11+Z11+AC11+AF11+AI11+AL11+AO11 -> 1329.631 | CX11: =I11+L11+O11+R11+U11+X11+AD11+AG11+AJ11+AM11+AP11 -> 50 | CY11: =CV11-D11 -> -2.15
B12: GPS | C12: A3
B13: GPS | C13: Total | D13: 84.2 | E13: =E11 -> 3400 | F13: =F11 -> 186 | G13: 82.61917 | H13: 85.396 | I13: 4 | M13: 87.48 | N13: 127.309 | O13: 5 | P13: 69.36 | Q13: 50.223 | R13: 2 | S13: 82.88 | T13: 101.957 | U13: 4 | V13: 86.53 | W13: 154.495 | X13: 6 | Y13: 84.64 | Z13: 103.418 | AA13: 4 | AB13: 77.91 | AC13: 102.977 | AD13: 4 | AE13: 76.08 | AF13: 103.567 | AG13: 4 | AH13: 78.74 | AI13: 166.269 | AJ13: 7 | AK13: 85.36 | AL13: 153.569 | AM13: 6 | AN13: 78.01 | AO13: 74.336 | AP13: 3 | CV13: 82.05 | CW13: =+H13+K13+N13+Q13+T13+W13+Z13+AC13+AF13+AI13+AL13+AO13 -> 1223.516 | CX13: =I13+L13+O13+R13+U13+X13+AD13+AG13+AJ13+AM13+AP13 -> 45 | CY13: =CV13-D13 -> -2.15
B14: PSL | C14: A | D14: 92.6 | E14: 7900 | F14: 562 | G14: 95.522597 | H14: 300.772 | I14: 19 | J14: 93.562286 | K14: 283.17 | L14: 19 | M14: 93.28 | N14: 308.993 | O14: 19 | P14: 93.73 | Q14: 260.356 | R14: 17 | S14: 91.28 | T14: 289.931 | U14: 19 | V14: 91.77 | W14: 259.485 | X14: 17 | Y14: 93.75 | Z14: 337.651 | AA14: 21 | AB14: 94.38 | AC14: 303.029 | AD14: 19 | AE14: 94.06 | AF14: 262.442 | AG14: 17 | AH14: 93.72 | AI14: 351.085 | AJ14: 23 | AK14: 94.51 | AL14: 321.809 | AM14: 21 | AN14: 95.49 | AO14: 278.323 | AP14: 18 | CV14: 93.77 | CW14: =+H14+K14+N14+Q14+T14+W14+Z14+AC14+AF14+AI14+AL14+AO14 -> 3557.046 | CX14: =I14+L14+O14+R14+U14+X14+AD14+AG14+AJ14+AM14+AP14 -> 208 | CY14: =CV14-D14 -> 1.17
B15: PSL | C15: B3 | D15: 93.8 | E15: 45300 | F15: 4338 | G15: 93.555091 | H15: 1824.459 | I15: 169 | J15: 93.303335 | K15: 1651.539 | L15: 154 | M15: 93.09 | N15: 1516.287 | O15: 132 | P15: 93.09 | Q15: 1692.552 | R15: 111 | S15: 93.19 | T15: 1592.169 | U15: 138 | V15: 92.7 | W15: 1385.136 | X15: 121 | Y15: 93.02 | Z15: 1381.101 | AA15: 120 | AB15: 92.08 | AC15: 1639.299 | AD15: 142 | AE15: 92.46 | AF15: 1902.388 | AG15: 165 | AH15: 93.76 | AI15: 1487.719 | AJ15: 129 | AK15: 93.87 | AL15: 1431.247 | AM15: 124 | AN15: 94.1 | AO15: 1356.207 | AP15: 118 | CV15: 93.16 | CW15: =+H15+K15+N15+Q15+T15+W15+Z15+AC15+AF15+AI15+AL15+AO15 -> 18860.103 | CX15: =I15+L15+O15+R15+U15+X15+AD15+AG15+AJ15+AM15+AP15 -> 1503 | CY15: =CV15-D15 -> -0.64
B16: PSL | C16: B15 | D16: 93 | E16: 1000 | F16: 122 | AK16: 80.37 | AL16: 46.261 | AM16: 4 | AN16: 79.9 | AO16: 79.337 | AP16: 7 | CV16: 80.07 | CY16: =CV16-D16 -> -12.93
B17: PSL | C17: B2 | D17: 94 | E17: 35100 | F17: 3338 | G17: 95.439807 | H17: 861.81 | I17: 78 | J17: 95.240786 | K17: 1090.427 | L17: 99 | M17: 94.01 | N17: 1227.894 | O17: 107 | P17: 95.06 | Q17: 1285.712 | R17: 147 | S17: 95.11 | T17: 1029.653 | U17: 89 | V17: 91.7 | W17: 1410.084 | X17: 122 | Y17: 92.17 | Z17: 1111.211 | AA17: 96 | AB17: 89.85 | AC17: 1680.219 | AD17: 145 | AE17: 90.04 | AF17: 1423.78 | AG17: 123 | AH17: 93.22 | AI17: 889.978 | AJ17: 77 | AK17: 90.48 | AL17: 1455.269 | AM17: 126 | AN17: 88.71 | AO17: 1364.783 | AP17: 118 | CV17: 92.29 | CW17: =+H17+K17+N17+Q17+T17+W17+Z17+AC17+AF17+AI17+AL17+AO17 -> 14830.82 | CX17: =I17+L17+O17+R17+U17+X17+AD17+AG17+AJ17+AM17+AP17 -> 1231 | CY17: =CV17-D17 -> -1.71
B18: PSG | C18: B2 | D18: 94.3 | E18: 36400 | F18: 3467 | G18: 92.715363 | H18: 1095.394 | I18: 102 | J18: 93.409201 | K18: 1336.936 | L18: 124 | M18: 91.63 | N18: 1257.494 | O18: 109 | P18: 92.9 | Q18: 1212.394 | R18: 105 | S18: 92.76 | T18: 1456.965 | U18: 126 | V18: 93.43 | W18: 1330.735 | X18: 115 | Y18: 92.93 | Z18: 1906.878 | AA18: 165 | AB18: 92.91 | AC18: 1144.348 | AD18: 99 | AE18: 94.73 | AF18: 1180.795 | AG18: 102 | AH18: 94.36 | AI18: 1690.891 | AJ18: 146 | AK18: 93.93 | AL18: 1330.725 | AM18: 115 | AN18: 94.72 | AO18: 1203.207 | AP18: 104 | CV18: 93.37 | CW18: =+H18+K18+N18+Q18+T18+W18+Z18+AC18+AF18+AI18+AL18+AO18 -> 16146.762 | CX18: =I18+L18+O18+R18+U18+X18+AD18+AG18+AJ18+AM18+AP18 -> 1247 | CY18: =CV18-D18 -> -0.93
B19: PSH | C19: B2 | D19: 94 | E19: 1800 | F19: 193 | G19: 92.449465 | H19: 127.008 | I19: 12 | M19: 89.15 | N19: 115.909 | O19: 10 | P19: 90.99 | Q19: 104.49 | R19: 9 | S19: 91.22 | T19: 80.495 | U19: 7 | V19: 92.09 | W19: 127.128 | X19: 11 | Y19: 90.03 | Z19: 11.654 | AA19: 1 | AB19: 81.69 | AC19: 69.007 | AD19: 6 | AE19: 89.39 | AF19: 185.556 | AG19: 16 | AH19: 94.61 | AI19: 139.636 | AJ19: 12 | AK19: 92.81 | AL19: 265.512 | AM19: 23 | AN19: 94.72 | AO19: 172.406 | AP19: 15 | CV19: 91.59 | CW19: =+H19+K19+N19+Q19+T19+W19+Z19+AC19+AF19+AI19+AL19+AO19 -> 1398.801 | CX19: =I19+L19+O19+R19+U19+X19+AD19+AG19+AJ19+AM19+AP19 -> 121 | CY19: =CV19-D19 -> -2.41
B20: PSU | C20: B2 | D20: 94 | E20: 400 | F20: 43
B21: STD | C21: Total | D21: 93.757082 | E21: =SUM(E14:E20) -> 127900 | F21: =SUM(F14:F20) -> 12063 | G21: 93.8175 | H21: 4209.443 | I21: 380 | J21: 93.829934 | K21: 4362.072 | L21: 396 | M21: 92.84 | N21: 4426.577 | O21: 377 | P21: 93.58 | Q21: 4555.504 | R21: 389 | S21: 93.33 | T21: 4449.213 | U21: 379 | V21: 92.53 | W21: 4512.568 | X21: 386 | Y21: 92.83 | Z21: 4748.495 | AA21: 403 | AB21: 91.5 | AC21: 4835.902 | AD21: 411 | AE21: 92.28 | AF21: 4954.961 | AG21: 423 | AH21: 93.9 | AI21: 4559.309 | AJ21: 387 | AK21: 92.73 | AL21: 4850.823 | AM21: 413 | AN21: 92.47 | AO21: 4454.263 | AP21: 380 | CV21: 92.96 | CW21: =+H21+K21+N21+Q21+T21+W21+Z21+AC21+AF21+AI21+AL21+AO21 -> 54919.13 | CX21: =I21+L21+O21+R21+U21+X21+AD21+AG21+AJ21+AM21+AP21 -> 4321 | CY21: =CV21-D21 -> -0.79708228
B22: Grand | C22: Total | D22: 93.121631 | E22: =E10+E13+E21 -> 152300 | F22: =F10+F13+F21 -> 13958.274 | G22: 93.325493 | H22: 5074.206 | I22: 439 | J22: 92.942894 | K22: 5305.712 | L22: 459 | M22: 92.3 | N22: 5397.064 | O22: 435 | P22: 92.89 | Q22: 5570.117 | R22: 452 | S22: 92.43 | T22: 5544.513 | U22: 447 | V22: 91.85 | W22: 5580.192 | X22: 451 | Y22: 92.23 | Z22: 5734.576 | AA22: 463 | AB22: 91.27 | AC22: 5893.678 | AD22: 476 | AE22: 91.88 | AF22: 6068.555 | AG22: 492 | AH22: 92.71 | AI22: 5619.823 | AJ22: 451 | AK22: 92.32 | AL22: 5904.041 | AM22: 476 | AN22: 91.92 | AO22: 5426.635 | AP22: 440 | CV22: 92.33 | CW22: =+H22+K22+N22+Q22+T22+W22+Z22+AC22+AF22+AI22+AL22+AO22 -> 67119.112 | CX22: =I22+L22+O22+R22+U22+X22+AD22+AG22+AJ22+AM22+AP22 -> 5018 | CY22: =CV22-D22 -> -0.79163093
A23: By P/N | B23: FPS | C23: A081C226M | G23: 89.270073 | H23: 237.262 | I23: 14 | J23: 86.866117 | K23: 246.857 | L23: 15 | M23: 88.07 | N23: 302.512 | O23: 16 | P23: 88.39 | Q23: 321.496 | R23: 17 | S23: 85.95 | T23: 303.392 | U23: 16 | V23: 86.08 | W23: 225.712 | X23: 12 | Y23: 88.31 | Z23: 304.251 | AA23: 16 | AB23: 88.26 | AC23: 266.823 | AD23: 14 | AE23: 89.11 | AF23: 282.78 | AG23: 15 | AH23: 85.85 | AI23: 303.518 | AJ23: 16 | AK23: 89.26 | AL23: 264.878 | AM23: 14 | AN23: 87.25 | AO23: 303 | AP23: 16 | CV23: 87.73 | CW23: =+H23+K23+N23+Q23+T23+W23+Z23+AC23+AF23+AI23+AL23+AO23 -> 3362.481 | CX23: =I23+L23+O23+R23+U23+X23+AD23+AG23+AJ23+AM23+AP23 -> 165 | CY23: =CV23-D23 -> 87.73
B24: FPS | C24: A30J107M | G24: 91.833547 | H24: 156.972 | I24: 9 | J24: 86.353727 | K24: 198.054 | L24: 12 | M24: 87.33 | N24: 198.566 | O24: 12 | P24: 88.01 | Q24: 228 | R24: 12 | S24: 84.72 | T24: 178.054 | U24: 11 | V24: 86.44 | W24: 180.766 | X24: 11 | Y24: 85.26 | Z24: 147.175 | AA24: 9 | AB24: 89.74 | AC24: 51.132 | AD24: 3 | AE24: 88.43 | AF24: 151.895 | AG24: 9 | AH24: 86.2 | AI24: 131.031 | AJ24: 8 | AK24: 88.72 | AL24: 151.568 | AM24: 9 | AN24: 89.14 | AO24: 153.092 | AP24: 8 | CV24: 87.476978 | CW24: =+H24+K24+N24+Q24+T24+W24+Z24+AC24+AF24+AI24+AL24+AO24 -> 1926.305 | CX24: =I24+L24+O24+R24+U24+X24+AD24+AG24+AJ24+AM24+AP24 -> 104 | CY24: =CV24-D24 -> 87.476978
B25: FPS | C25: B30E337
B26: PSG | C26: B20E337M | G26: 92.715363 | H26: 1095.394 | I26: 102 | J26: 93.409201 | K26: 1336.936 | L26: 124 | M26: 91.63 | N26: 1257.494 | O26: 109 | P26: 92.9 | Q26: 1212.394 | R26: 105 | S26: 92.76 | T26: 1456.965 | U26: 126 | V26: 93.43 | W26: 1330.735 | X26: 115 | Y26: 92.93 | Z26: 1906.878 | AA26: 165 | AB26: 92.91 | AC26: 1144.348 | AD26: 99 | AE26: 94.73 | AF26: 1180.795 | AG26: 102 | AH26: 94.36 | AI26: 1690.891 | AJ26: 146 | AK26: 93.93 | AL26: 1330.725 | AM26: 115 | AN26: 94.72 | AO26: 1203.207 | AP26: 104 | CV26: 93.37 | CW26: =+H26+K26+N26+Q26+T26+W26+Z26+AC26+AF26+AI26+AL26+AO26 -> 16146.762 | CX26: =I26+L26+O26+R26+U26+X26+AD26+AG26+AJ26+AM26+AP26 -> 1247 | CY26: =CV26-D26 -> 93.37
B27: PSL | C27: B20E477M | V27: 73.71 | W27: 85.429 | X27: 10 | Y27: 73.51 | Z27: 59.535 | AA27: 7 | AB27: 81.18 | AC27: 291.332 | AD27: 31 | AE27: 77.65 | AF27: 90.095 | AG27: 10 | AH27: 78.65 | AI27: 27.371 | AJ27: 4 | AK27: 74.04 | AL27: 162.507 | AM27: 19 | AN27: 64.43 | AO27: 141.827 | AP27: 19 | CV27: 74.86 | CW27: =+H27+K27+N27+Q27+T27+W27+Z27+AC27+AF27+AI27+AL27+AO27 -> 858.096 | CX27: =I27+L27+O27+R27+U27+X27+AD27+AG27+AJ27+AM27+AP27 -> 93 | CY27: =CV27-D27 -> 74.86
B28: PSL | C28: B20J227M25SK8R
B29: PSL | C29: B30J157M | G29: 91.815511 | H29: 771.994 | I29: 73 | J29: 91.941059 | K29: 643.17 | L29: 61 | M29: 92.86 | N29: 595.179 | O29: 56 | P29: 92.4 | Q29: 883 | R29: 77 | S29: 91.75 | T29: 644.001 | U29: 61 | V29: 91.97 | W29: 741.01 | X29: 70 | Y29: 92.5 | Z29: 817.491 | AA29: 77 | AB29: 90.08 | AC29: 665.557 | AD29: 64 | AE29: 90.75 | AF29: 618.002 | AG29: 59 | AH29: 92.62 | AI29: 438.747 | AJ29: 41 | AK29: 92.71 | AL29: 642.39 | AM29: 60 | AN29: 93.8 | AO29: 679.778 | AP29: 63 | CV29: 92.09 | CW29: =+H29+K29+N29+Q29+T29+W29+Z29+AC29+AF29+AI29+AL29+AO29 -> 8140.319 | CX29: =I29+L29+O29+R29+U29+X29+AD29+AG29+AJ29+AM29+AP29 -> 685 | CY29: =CV29-D29 -> 92.09
A34: Date | B34: Series | C34: Problem | D34: Analysis/ Action | G34: PIC | I34: Progress | P34: Due Date
A35: 46246 | B35: FPSA3 (A30J107) | C35: ESR Problem from L/F lot and Problems beyond L/F. Inprocess-DW CAM3 Dimension | D35: ESR : Remaining WIP for L/F problem = 6 Lots Problems beyond L/F. --> Focus to Mold clamp. CAM-3 defect occurrence appears to be related to both the dicing process and the Pick & Place (P&P) machine. A significant difference in defect levels has been observed among machines, with some showing normal performance while others exhibit considerably higher defect rates. | G35: Mr. Jirapat Mr. Pawekorn | I35: ESR '1. Feedback to supplier about L/F dimension. 2. Standardize L/F dimensional control to reduce ESR variation. | P35: 46248
B36: FPSA08 (A081C226) | C36: In-process-DW CAM3 Dimension CAM2 Mold-chip | D36: CAM-3 defect occurrence appears to be related to both the dicing process and the Pick & Place (P&P) machine. A significant difference in defect levels has been observed among machines, with some showing normal performance while others exhibit considerably higher defect rates. LC shift at ACC is a reversible heat and moisture effect, not permanent dielectric damage. The recovery after M-Treatment confirms that the change is temporary and moisture-related. SMT LC shift is a reversible thermal/moisture-related phenomenon rather than permanent degradation. | G36: Ms. Sasitorn Ms. Chotmanee | I36: CAM-3 : Further investigation is required to identify the specific machine conditions and mechanisms contributing to the variation. ACC/SMT - Temporary Action: Optimize moisture control during ACC/SMT to minimize the reversible LC shift. - Permanent Action: Identify and eliminate the root cause at ACC by improving dielectric uniformity and stability. | P36: 46252
B37: PSGB2 (B20E337) | C37: ESR Blister: Conveyer machine make bubble of GB2,B2 | D37: ESR was high deviation in some lot, PSGB2 was high sensivity. (1) From analysis found polymer had black spot at internal polymer that means inner is not cover well (2)Another is insulate of polymer was not get good insulatuin peak so LC high & get ESR high also. Blister : Conveyer had high temp & low hu at machine no Z1, EE BOL already fix it & GB2 case specify to not apply this machine (shape of anode were effect to blister). | G37: Ms. Supatsara Ms. Paemika Ms. Kanlaya | I37: First, conduct a detailed analysis to identify the process factors contributing to the ESR differences between the low ESR and high ESR groups, and determine the key parameters driving the variation We are currently investigating potential blister formation associated with abnormalities in the NR conveyor of the Z1 equipment. The objective is to clarify the blister formation mechanism, identify the root cause, and implement permanent corrective actions to prevent recurrence. | P37: 46248
B38: PSLB2 (B20E477) | C38: ESR High powder grade LC Weak at welding machine | D38: ESR level and variability increased after 250KCV implementation. However, the presence of both good and bad lots suggests that process variation remains, requiring further investigation to identify and eliminate the sources of inconsistency LC --> check LC tendency by M/C amd LC before/after welding | G38: Ms. Supatsara Ms. Paemika Ms. Kanlaya | I38: First, conduct a detailed analysis to identify the process factors contributing to the ESR differences between the low ESR and high ESR groups, and determine the key parameters driving the variation QOD to improve LC by change M-Aging volt from 2.5 to 5V (Today Aug 13'26 apply 3 lot of change review) -->This action will get benefit to ESR | P38: E/Aug'26
B39: PSLB2 (B20J107) (B21A107) (B21C336) | C39: App : Terminal Red | D39: From Analysis data -Gule mixing condition was not good (A&B) was not mix well -Consider another factor | G39: Ms. Supatsara Ms. Chantira Mr. Nonthawat | I39: -Finished experiment Mazerustar mixing machine, get good result for homogenous -Trial on 13 Aug,26 on 2HD(FA8) welding machine 3 lots, wait for result | P39: 46248
B40: PSLB15 | C40: Terminal red B150J227M | G40: TE (NPD) Suwicha Narakorn Team
A41: 46245 | B41: FPSA3 (A30J107) | C41: ESR Problem from L/F lot | D41: Remaining WIP for L/F problem | G41: Mr. Jirapat Mr. Pawekorn | I41: 1. Feedback to supplier about L/F dimension. 2. Work closely with QA to monitor L/F dimensional variation and its impact on ESR performance, and establish standardized control criteria. | P41: 46248
B42: FPSA2 (A21N396) | C42: App : Terminal Scratch CO : SH (Open) | D42: Root cause investigation is ongoing. (Terminal scratch --> 4M checking) | G42: Ms. Sasitorn Ms. Chotmanee Ms. Parichat Mr. Taksin | I42: 1. Clarify the defective with marginal sample with QA team and check the solderability test for verify functionality. 2. Conduct an on-site inspection to verify the defect mechanism and identify potential contributing factors. | P42: 46248
B43: PSGB2 (B20E337) | C43: ESR & Blister Blister: Conveyer machine make bubble of GB2,B2 | D43: ESR was high deviation in some lot, PSGB2 was high sensivity. (1) From analysis found polymer had black spot at internal polymer that means inner is not cover well (2)Another is insulate of polymer was not get good insulatuin peak so LC high & get ESR high also. Blister : Conveyer had high temp & low hu at machine no Z1, EE BOL already fix it & GB2 case specify to not apply this machine (shape of anode were effect to blister). | G43: Ms. Supatsara Ms. Paemika Ms. Kanlaya | I43: First, conduct a detailed analysis to identify the process factors contributing to the ESR differences between the low ESR and high ESR groups, and determine the key parameters driving the variation We are currently investigating potential blister formation associated with abnormalities in the NR conveyor of the Z1 equipment. The objective is to clarify the blister formation mechanism, identify the root cause, and implement permanent corrective actions to prevent recurrence. | P43: 46248
B44: PSLB2 (B20E477) | C44: ESR and LC | D44: ESR level and variability increased after 250KCV implementation. However, the presence of both good and bad lots suggests that process variation remains, requiring further investigation to identify and eliminate the sources of inconsistency LC --> check LC tendency by M/C amd LC before/after welding | G44: Ms. Supatsara Ms. Paemika Ms. Kanlaya | I44: First, conduct a detailed analysis to identify the process factors contributing to the ESR differences between the low ESR and high ESR groups, and determine the key parameters driving the variation | P44: E/Aug'26
...

Sheet Monthly_Yield_Ta-SC
D2: CY2025 | P2: CY2026
B3: Sub | C3: Case | D3: Jan'25 | E3: Feb | F3: Mar | G3: Apr | H3: May | I3: Jun | J3: Jul | K3: Aug | L3: Sep | M3: Oct | N3: Nov | O3: Dec | P3: Jan'26 | Q3: Feb | R3: Mar | S3: Apr | T3: May | U3: Jun | V3: Jul | W3: Aug | X3: Sep | Y3: Oct | Z3: Nov | AA3: Dec
A4: TaPoly | B4: FPS | C4: A3 | D4: 0.9147 | E4: 0.902 | F4: 0.9119 | G4: 0.9092 | H4: 0.9157 | I4: 0.9152 | J4: 0.9033 | K4: 0.8987 | L4: 0.8979 | M4: 0.8941 | N4: 0.891 | O4: 0.8725 | P4: 0.8631 | Q4: 0.8582 | R4: 0.8607 | S4: 0.8838 | T4: 0.9068 | U4: 0.901 | V4: 0.8924
A5: (E/I) | B5: FPS | C5: A2 | D5: 0.9338 | E5: 0.9422 | F5: 0.9388 | G5: 0.9307 | H5: 0.9168 | I5: 0.9307 | J5: 0.9393 | K5: 0.9448 | L5: 0.9508 | M5: 0.9456 | N5: 0.9493 | O5: 0.9476 | P5: 0.9363 | Q5: 0.9339 | R5: 0.9256 | S5: 0.9346 | T5: 0.9376 | U5: 0.9041 | V5: 0.9331
B6: FPS | C6: B3 | D6: 0.8877 | E6: 0.9425 | F6: 0.9264 | G6: 0.8589 | H6: 0.9034 | I6: 0.9028 | J6: 0.9164 | K6: 0.8691 | L6: 0.8705 | M6: 0.9352 | N6: 0.9308 | O6: 0.9293 | P6: 0.9285 | Q6: 0.9256 | R6: 0.9237 | S6: 0.9435 | T6: 0.9271 | U6: 0.9248 | V6: 0.9071
B7: FPS | C7: B10 | D7: 0.9257 | E7: 0.9304 | F7: 0.9273 | G7: 0.9297 | H7: 0.9161 | I7: 0.9167 | J7: 0.8824 | K7: 0.925 | L7: 0.8974 | M7: - | N7: - | O7: 0.8409 | P7: 0.9015 | Q7: 0.916 | R7: 0.9093 | S7: 0.9309 | T7: 0.9329 | U7: 0.9224
B8: FPS | C8: A08 | D8: 0.855 | E8: 0.822 | F8: 0.8582 | G8: 0.8634 | H8: 0.8127 | I8: 0.7869 | J8: 0.7675 | K8: 0.7377 | L8: 0.7293 | M8: 0.7469 | N8: 0.732 | O8: 0.8229 | P8: 0.8529 | Q8: 0.8752 | R8: 0.8456 | S8: 0.7945 | T8: 0.8572 | U8: 0.87 | V8: 0.848
B9: FPU | C9: A2 | V9: 0.7178
B10: FACE DOWN | C10: Total | D10: 0.9125 | E10: 0.9235 | F10: 0.9284 | G10: 0.9121 | H10: 0.904 | I10: 0.9097 | J10: 0.902 | K10: 0.8609 | L10: 0.8787 | M10: 0.8999 | N10: 0.8799 | O10: 0.896 | P10: 0.9051 | Q10: 0.9143 | R10: 0.8982 | S10: 0.9037 | T10: 0.9044 | U10: 0.901 | V10: 0.8835
B11: GPS | C11: P2 | D11: 0.8103 | E11: 0.835 | F11: 0.8567 | G11: 0.8312 | H11: 0.8408 | I11: 0.8099 | J11: 0.8024 | K11: 0.8479 | L11: 0.8314 | M11: 0.8494 | N11: 0.8338 | O11: 0.8684 | P11: 0.8173 | Q11: 0.7924 | R11: 0.8096 | S11: 0.8445 | T11: 0.8361 | U11: 0.8341 | V11: 0.8195
B12: GPS | C12: A3
B13: GPS | C13: Total | D13: 0.8103 | E13: 0.835 | F13: 0.8567 | G13: 0.8312 | H13: 0.8408 | I13: 0.8099 | J13: 0.8024 | K13: 0.8479 | L13: 0.8314 | M13: 0.8494 | N13: 0.8338 | O13: 0.8684 | P13: 0.8173 | Q13: 0.7924 | R13: 0.8096 | S13: 0.8445 | T13: 0.8361 | U13: 0.8341 | V13: 0.8195
B14: PSL | C14: A | D14: 0.9396 | E14: 0.9353 | F14: 0.9336 | G14: 0.92 | H14: 0.9287 | I14: 0.9284 | J14: 0.9129 | K14: 0.9218 | L14: 0.9209 | M14: 0.9331 | N14: 0.9363 | O14: 0.9378 | P14: 0.9425 | Q14: 0.9501 | R14: 0.9558 | S14: 0.9488 | T14: 0.948 | U14: 0.9446 | V14: 0.926
B15: PSL | C15: B3 | D15: 0.9337 | E15: 0.9322 | F15: 0.943 | G15: 0.9456 | H15: 0.9492 | I15: 0.9431 | J15: 0.9415 | K15: 0.9404 | L15: 0.9343 | M15: 0.9319 | N15: 0.9221 | O15: 0.9206 | P15: 0.9256 | Q15: 0.9258 | R15: 0.9224 | S15: 0.9327 | T15: 0.9347 | U15: 0.9282 | V15: 0.9248
B16: PSL | C16: B15 | D16: 0.9086 | E16: 0.937 | F16: 0.9433 | G16: 0.9335 | H16: 0.7734 | I16: - | J16: 0.8759 | K16: 0.9232 | L16: 0.8821 | M16: 0.9303 | N16: 0.9434 | O16: 0.8949 | P16: 0.7986 | Q16: 0.8689 | R16: 0.897 | S16: 0.8823 | T16: 0.819 | U16: 0.8329 | V16: 0.7903
B17: PSL | C17: B2 | D17: 0.9559 | E17: 0.9532 | F17: 0.9552 | G17: 0.9465 | H17: 0.9511 | I17: 0.9411 | J17: 0.928 | K17: 0.9286 | L17: 0.9281 | M17: 0.9337 | N17: 0.9393 | O17: 0.9075 | P17: 0.9174 | Q17: 0.9429 | R17: 0.917 | S17: 0.9309 | T17: 0.9274 | U17: 0.9314 | V17: 0.9334
B18: PSG | C18: B2 | D18: 0.9532 | E18: 0.9538 | F18: 0.9554 | G18: 0.9488 | H18: 0.9488 | I18: 0.942 | J18: 0.9315 | K18: 0.9397 | L18: 0.934 | M18: 0.9375 | N18: 0.9408 | O18: 0.9301 | P18: 0.919 | Q18: 0.9402 | R18: 0.9453 | S18: 0.9417 | T18: 0.9367 | U18: 0.928 | V18: 0.9267
B19: PSH | C19: B2 | D19: 0.9478 | E19: 0.9336 | F19: 0.9491 | G19: 0.9064 | H19: 0.9356 | I19: 0.9407 | J19: 0.9325 | K19: 0.9353 | L19: 0.9508 | M19: 0.9348 | N19: 0.9316 | O19: 0.9362 | P19: 0.9387 | Q19: 0.9396 | R19: 0.9384 | S19: 0.9445 | T19: 0.9282 | U19: 0.9405 | V19: 0.9221
B20: PSU | C20: B2 | D20: 0.9465 | E20: 0.9588 | F20: 0.951 | G20: 0.9495 | H20: 0.947 | I20: 0.9598 | J20: 0.952 | K20: - | L20: 0.9455 | M20: 0.9348 | N20: 0.8799 | O20: 0.9312 | P20: - | Q20: - | R20: 0.9432 | S20: 0.9532 | T20: 0.9507 | U20: 0.9533 | V20: 0.94
B21: STD | C21: Total | D21: 0.9453 | E21: 0.9453 | F21: 0.9493 | G21: 0.9443 | H21: 0.9481 | I21: 0.9417 | J21: 0.9328 | K21: 0.9346 | L21: 0.9302 | M21: 0.9336 | N21: 0.933 | O21: 0.9194 | P21: 0.9235 | Q21: 0.9364 | R21: 0.9278 | S21: 0.9347 | T21: 0.9325 | U21: 0.9308 | V21: 0.9245
B22: Grand | C22: Total | D22: 0.9404 | E22: 0.9401 | F22: 0.9454 | G22: 0.937 | H22: 0.9385 | I22: 0.9319 | J22: 0.9249 | K22: 0.924 | L22: 0.9225 | M22: 0.9273 | N22: 0.9227 | O22: 0.914 | P22: 0.9179 | Q22: 0.9295 | R22: 0.9203 | S22: 0.9279 | T22: 0.9258 | U22: 0.9239 | V22: 0.9149
A23: SC | B23: Can | D23: 0.988 | E23: 0.9841 | F23: 0.986 | G23: 0.9858 | H23: 0.9855 | I23: 0.9831 | J23: 0.9841 | K23: 0.98217 | L23: 0.9839 | M23: 0.9809 | N23: 0.9841 | O23: 0.9836 | P23: 0.986 | Q23: 0.9847 | R23: 0.9847 | S23: 0.9843 | T23: 0.9832 | U23: 0.9856
A24: (End Prod) | B24: FC | D24: 0.9897 | E24: 0.9926 | F24: 0.9918 | G24: 0.9905 | H24: 0.9912 | I24: 0.9918 | J24: 0.993 | K24: 0.99299 | L24: 0.9933 | M24: 0.9919 | N24: 0.9934 | O24: 0.9931 | P24: 0.9937 | Q24: 0.9937 | R24: 0.9927 | S24: 0.9924 | T24: 0.9931 | U24: 0.9927
B25: FM | D25: 0.9937 | E25: 0.9938 | F25: 0.9928 | G25: 0.9921 | H25: 0.992 | I25: 0.9927 | J25: 0.9922 | K25: 0.99286 | L25: 0.9916 | M25: 0.9923 | N25: 0.9902 | O25: 0.9904 | P25: 0.9919 | Q25: 0.9929 | R25: 0.993 | S25: 0.9932 | T25: 0.9945 | U25: 0.9941
B26: Grand Total | D26: 0.9913 | E26: 0.9903 | F26: 0.9907 | G26: 0.9897 | H26: 0.9901 | I26: 0.9899 | J26: 0.9904 | K26: 0.99063 | L26: 0.9901 | M26: 0.9891 | N26: 0.9896 | O26: 0.9898 | P26: 0.991 | Q26: 0.9911 | R26: 0.9907 | S26: 0.9906 | T26: 0.9909 | U26: 0.9916

Sheet Daily_Yield_SC
A1: =TODAY()-1 -> 46247
D3: Target | G3: 46235 | J3: 46236 | M3: 46237 | P3: 46238 | S3: 46239 | V3: 46240 | Y3: 46241 | AB3: 46242 | AE3: 46243 | AH3: 46244 | AK3: 46245 | AN3: 46246 | AQ3: 46247 | AT3: 46248 | AW3: 46249 | AZ3: 46250 | BC3: 46251 | BF3: 46252 | BI3: 46253 | BL3: 46254 | BO3: 46255 | BR3: 46256 | BU3: 46257 | BX3: 46258 | CA3: 46259 | CD3: 46260 | CG3: 46261 | CJ3: 46262 | CM3: 46263 | CP3: 46264 | CS3: 46265 | CV3: MTD
B4: Sub | C4: Case | D4: %Yield | E4: Output (KP) | F4: Lot | G4: %Yield | H4: Output (KP) | I4: Lot | J4: %Yield | K4: Output (KP) | L4: Lot | M4: %Yield | N4: Output (KP) | O4: Lot | P4: %Yield | Q4: Output (KP) | R4: Lot | S4: %Yield | T4: Output (KP) | U4: Lot | V4: %Yield | W4: Output (KP) | X4: Lot | Y4: %Yield | Z4: Output (KP) | AA4: Lot | AB4: %Yield | AC4: Output (KP) | AD4: Lot | AE4: %Yield | AF4: Output (KP) | AG4: Lot | AH4: %Yield | AI4: Output (KP) | AJ4: Lot | AK4: %Yield | AL4: Output (KP) | AM4: Lot | AN4: %Yield | AO4: Output (KP) | AP4: Lot | AQ4: %Yield | AR4: Output (KP) | AS4: Lot | AT4: %Yield | AU4: Output (KP) | AV4: Lot | AW4: %Yield | AX4: Output (KP) | AY4: Lot | AZ4: %Yield | BA4: Output (KP) | BB4: Lot | BC4: %Yield | BD4: Output (KP) | BE4: Lot | BF4: %Yield | BG4: Output (KP) | BH4: Lot | BI4: %Yield | BJ4: Output (KP) | BK4: Lot | BL4: %Yield | BM4: Output (KP) | BN4: Lot | BO4: %Yield | BP4: Output (KP) | BQ4: Lot | BR4: %Yield | BS4: Output (KP) | BT4: Lot | BU4: %Yield | BV4: Output (KP) | BW4: Lot | BX4: %Yield | BY4: Output (KP) | BZ4: Lot | CA4: %Yield | CB4: Output (KP) | CC4: Lot | CD4: %Yield | CE4: Output (KP) | CF4: Lot | CG4: %Yield | CH4: Output (KP) | CI4: Lot | CJ4: %Yield | CK4: Output (KP) | CL4: Lot | CM4: %Yield | CN4: Output (KP) | CO4: Lot | CP4: %Yield | CQ4: Output (KP) | CR4: Lot | CS4: %Yield | CT4: Output (KP) | CU4: Lot | CV4: %Yield | CW4: Output (KP) | CX4: Lot | CY4: Diff with Target
A5: SC | B5: Can | D5: 98.45 | E5: 750 | F5: 132 | G5: 95.8 | H5: =21367/1000 -> 21.367 | I5: 4 | J5: 99.44 | K5: =8853/1000 -> 8.853 | L5: 2 | M5: 98.18 | N5: =34982/1000 -> 34.982 | O5: 7 | P5: 98.73 | Q5: =31273/1000 -> 31.273 | R5: 7 | S5: 98.64 | T5: =27283/1000 -> 27.283 | U5: 3 | V5: 98.76 | W5: =63511/1000 -> 63.511 | X5: 9 | Y5: 98.59 | Z5: =11733/1000 -> 11.733 | AA5: 2 | AB5: 98.58 | AC5: =12655/1000 -> 12.655 | AD5: 1 | AE5: 98.93 | AF5: =11240/1000 -> 11.24 | AG5: 3 | AH5: 96.88 | AI5: =10361/1000 -> 10.361 | AJ5: 4 | AK5: 98.57 | AL5: =51765/1000 -> 51.765 | AM5: 9 | AO5: 0 | AP5: 0 | CV5: =AVERAGE(G5,J5,M5,P5,S5,V5,Y5,AB5,AE5,AH5,AK5,AN5,AQ5,AT5,AW5,AZ5,BC5,BF5,BI5,BL5,BO5,BR5,BU5,BX5,CA5,CD5,CG5,CJ5,CM5,CP5,CS5) -> 98.281818 | CW5: =SUM(H5,K5,N5,Q5,T5,W5,Z5,AC5,AF5,AI5,AL5,AO5,AR5,AU5,AX5,BA5,BD5,BG5,BJ5,BM5,BP5,BS5,BV5,BY5,CB5,CE5,CH5,CK5,CN5,CQ5,CT5) -> 285.023 | CX5: =SUM(I5,L5,O5,R5,U5,X5,AA5,AD5,AG5,AJ5,AM5,AP5,AS5,AV5,AY5,BB5,BE5,BH5,BK5,BN5,BQ5,BT5,BW5,BZ5,CC5,CF5,CI5,CL5,CO5,CR5,CU5) -> 51 | CY5: =CV5-D5 -> -0.16818182
A6: (End Prod) | B6: FC | D6: 99.1 | E6: 1600 | F6: 121 | G6: 99.42 | H6: =30000/1000 -> 30 | I6: 3 | J6: 99.36 | K6: =49000/1000 -> 49 | L6: 4 | M6: 99.01 | N6: =37500/1000 -> 37.5 | O6: 3 | P6: 99.3 | Q6: =74000/1000 -> 74 | R6: 6 | S6: 98.92 | T6: =36500/1000 -> 36.5 | U6: 3 | V6: 99.25 | W6: =77000/1000 -> 77 | X6: 6 | Y6: 99 | Z6: =54900/1000 -> 54.9 | AA6: 5 | AB6: 99.05 | AC6: =20500/1000 -> 20.5 | AD6: 2 | AE6: 98.99 | AF6: =36700/1000 -> 36.7 | AG6: 3 | AH6: 99.07 | AI6: =86200/1000 -> 86.2 | AJ6: 7 | AK6: 99.45 | AL6: =81500/1000 -> 81.5 | AM6: 5 | AO6: 0 | AP6: 0 | CV6: =AVERAGE(G6,J6,M6,P6,S6,V6,Y6,AB6,AE6,AH6,AK6,AN6,AQ6,AT6,AW6,AZ6,BC6,BF6,BI6,BL6,BO6,BR6,BU6,BX6,CA6,CD6,CG6,CJ6,CM6,CP6,CS6) -> 99.165455 | CW6: =SUM(H6,K6,N6,Q6,T6,W6,Z6,AC6,AF6,AI6,AL6,AO6,AR6,AU6,AX6,BA6,BD6,BG6,BJ6,BM6,BP6,BS6,BV6,BY6,CB6,CE6,CH6,CK6,CN6,CQ6,CT6) -> 583.8 | CX6: =SUM(I6,L6,O6,R6,U6,X6,AA6,AD6,AG6,AJ6,AM6,AP6,AS6,AV6,AY6,BB6,BE6,BH6,BK6,BN6,BQ6,BT6,BW6,BZ6,CC6,CF6,CI6,CL6,CO6,CR6,CU6) -> 47 | CY6: =CV6-D6 -> 0.065454545
B7: FM | D7: 99.2 | E7: 1200 | F7: 91 | G7: 99.59 | H7: =59067/1000 -> 59.067 | I7: 4 | J7: 99.63 | K7: =17000/1000 -> 17 | L7: 1 | N7: 0 | O7: 0 | P7: 99.71 | Q7: =9000/1000 -> 9 | R7: 1 | S7: 99.54 | T7: =106879/1000 -> 106.879 | U7: 8 | V7: 99.46 | W7: =80198/1000 -> 80.198 | X7: 7 | Y7: 99.55 | Z7: =31729/1000 -> 31.729 | AA7: 2 | AB7: 99.7 | AC7: =9063/1000 -> 9.063 | AD7: 1 | AE7: 99.73 | AF7: =19000/1000 -> 19 | AG7: 1 | AH7: 99.5 | AI7: =35114/1000 -> 35.114 | AJ7: 3 | AK7: 99.57 | AL7: =38000/1000 -> 38 | AM7: 2 | AO7: 0 | AP7: 0 | CV7: =AVERAGE(G7,J7,M7,P7,S7,V7,Y7,AB7,AE7,AH7,AK7,AN7,AQ7,AT7,AW7,AZ7,BC7,BF7,BI7,BL7,BO7,BR7,BU7,BX7,CA7,CD7,CG7,CJ7,CM7,CP7,CS7) -> 99.598 | CW7: =SUM(H7,K7,N7,Q7,T7,W7,Z7,AC7,AF7,AI7,AL7,AO7,AR7,AU7,AX7,BA7,BD7,BG7,BJ7,BM7,BP7,BS7,BV7,BY7,CB7,CE7,CH7,CK7,CN7,CQ7,CT7) -> 405.05 | CX7: =SUM(I7,L7,O7,R7,U7,X7,AA7,AD7,AG7,AJ7,AM7,AP7,AS7,AV7,AY7,BB7,BE7,BH7,BK7,BN7,BQ7,BT7,BW7,BZ7,CC7,CF7,CI7,CL7,CO7,CR7,CU7) -> 30 | CY7: =CV7-D7 -> 0.398
B8: Grand Total | D8: 99 | E8: =SUM(E5:E7) -> 3550 | F8: =SUM(F5:F7) -> 344 | G8: =(G5*H5/H8)+(G6*H6/H8)+(G7*H7/H8) -> 98.810521 | H8: =SUM(H5:H7) -> 110.434 | I8: =SUM(I5:I7) -> 11 | J8: =(J5*K5/K8)+(J6*K6/K8)+(J7*K7/K8) -> 99.430782 | K8: =SUM(K5:K7) -> 74.853 | L8: =SUM(L5:L7) -> 7 | M8: =(M5*N5/N8)+(M6*N6/N8)+(M7*N7/N8) -> 98.609417 | N8: =SUM(N5:N7) -> 72.482 | O8: =SUM(O5:O7) -> 10 | P8: =(P5*Q5/Q8)+(P6*Q6/Q8)+(P7*Q7/Q8) -> 99.1763 | Q8: =SUM(Q5:Q7) -> 114.273 | R8: =SUM(R5:R7) -> 14 | S8: =(S5*T5/T8)+(S6*T6/T8)+(S7*T7/T8) -> 99.26352 | T8: =SUM(T5:T7) -> 170.662 | U8: =SUM(U5:U7) -> 14 | V8: =(V5*W5/W8)+(V6*W6/W8)+(V7*W7/W8) -> 99.185305 | W8: =SUM(W5:W7) -> 220.709 | X8: =SUM(X5:X7) -> 22 | Y8: =(Y5*Z5/Z8)+(Y6*Z6/Z8)+(Y7*Z7/Z8) -> 99.128509 | Z8: =SUM(Z5:Z7) -> 98.362 | AA8: =SUM(AA5:AA7) -> 9 | AB8: =(AB5*AC5/AC8)+(AB6*AC6/AC8)+(AB7*AC7/AC8) -> 99.048652 | AC8: =SUM(AC5:AC7) -> 42.218 | AD8: =SUM(AD5:AD7) -> 4 | AE8: =(AE5*AF5/AF8)+(AE6*AF6/AF8)+(AE7*AF7/AF8) -> 99.189964 | AF8: =SUM(AF5:AF7) -> 66.94 | AG8: =SUM(AG5:AG7) -> 7 | AH8: =(AH5*AI5/AI8)+(AH6*AI6/AI8)+(AH7*AI7/AI8) -> 99.012346 | AI8: =SUM(AI5:AI7) -> 131.675 | AJ8: =SUM(AJ5:AJ7) -> 14 | AK8: =(AK5*AL5/AL8)+(AK6*AL6/AL8)+(AK7*AL7/AL8) -> 99.210645 | AL8: =SUM(AL5:AL7) -> 171.265 | AM8: =SUM(AM5:AM7) -> 16 | AN8: =(AN5*AO5/AO8)+(AN6*AO6/AO8)+(AN7*AO7/AO8) -> #DIV/0! | AO8: =SUM(AO5:AO7) -> 0 | AP8: =SUM(AP5:AP7) -> 0 | AQ8: =(AQ5*AR5/AR8)+(AQ6*AR6/AR8)+(AQ7*AR7/AR8) -> 0 | AR8: 181.088 | AS8: 21 | AT8: =(AT5*AU5/AU8)+(AT6*AU6/AU8)+(AT7*AU7/AU8) -> #DIV/0! | AU8: =SUM(AU5:AU7) -> 0 | AV8: =SUM(AV5:AV7) -> 0 | AW8: =(AW5*AX5/AX8)+(AW6*AX6/AX8)+(AW7*AX7/AX8) -> #DIV/0! | AX8: =SUM(AX5:AX7) -> 0 | AY8: =SUM(AY5:AY7) -> 0 | AZ8: =(AZ5*BA5/BA8)+(AZ6*BA6/BA8)+(AZ7*BA7/BA8) -> #DIV/0! | BA8: =SUM(BA5:BA7) -> 0 | BB8: =SUM(BB5:BB7) -> 0 | BC8: =(BC5*BD5/BD8)+(BC6*BD6/BD8)+(BC7*BD7/BD8) -> #DIV/0! | BD8: =SUM(BD5:BD7) -> 0 | BE8: =SUM(BE5:BE7) -> 0 | BF8: =(BF5*BG5/BG8)+(BF6*BG6/BG8)+(BF7*BG7/BG8) -> #DIV/0! | BG8: =SUM(BG5:BG7) -> 0 | BH8: =SUM(BH5:BH7) -> 0 | BI8: =(BI5*BJ5/BJ8)+(BI6*BJ6/BJ8)+(BI7*BJ7/BJ8) -> #DIV/0! | BJ8: =SUM(BJ5:BJ7) -> 0 | BK8: =SUM(BK5:BK7) -> 0 | BL8: =(BL5*BM5/BM8)+(BL6*BM6/BM8)+(BL7*BM7/BM8) -> #DIV/0! | BM8: =SUM(BM5:BM7) -> 0 | BN8: =SUM(BN5:BN7) -> 0 | BO8: =(BO5*BP5/BP8)+(BO6*BP6/BP8)+(BO7*BP7/BP8) -> #DIV/0! | BP8: =SUM(BP5:BP7) -> 0 | BQ8: =SUM(BQ5:BQ7) -> 0 | BR8: =(BR5*BS5/BS8)+(BR6*BS6/BS8)+(BR7*BS7/BS8) -> #DIV/0! | BS8: =SUM(BS5:BS7) -> 0 | BT8: =SUM(BT5:BT7) -> 0 | BU8: =(BU5*BV5/BV8)+(BU6*BV6/BV8)+(BU7*BV7/BV8) -> #DIV/0! | BV8: =SUM(BV5:BV7) -> 0 | BW8: =SUM(BW5:BW7) -> 0 | CV8: =(CV5*CW5/CW8)+(CV6*CW6/CW8)+(CV7*CW7/CW8) -> 99.10528 | CW8: =SUM(CW5:CW7) -> 1273.873 | CX8: =SUM(CX5:CX7) -> 128 | CY8: =CV8-D8 -> 0.10528045
A11: Date | B11: Series | C11: Problem | D11: Action | E11: PIC | F11: Progress
A12: 46244 | B12: FC | C12: SD Def from tighten SD spec for expired element | D12: Review SD spec | E12: PE | F12: On going
C13: SD def suspect over reject from operating at CC line. | D13: Keep maintain probe and panel. | E13: EE Mtnc. | F13: On going
C14: SD defective -> Re-screen liq-leak many round. | D14: Keep check & control process | E14: PE | F14: On going
C15: Laser Marking fade from change product size at plate inserting FC2 (8.4 mm to 8.1 mm). | D15: Issue adjusting instruction for product model change | E15: EE Mtnc. | F15: Not started
B16: CAN | C16: C def from over reject(defective was re-screened but unable to fix MES data) | D16: Confirm C meas. Cond. | E16: PE | F16: On going
A17: 46243 | B17: FC | C17: SD def suspect over reject from operating at CC line. | D17: Keep maintain probe and panel. | E17: EE Mtnc. | F17: On going
A18: 46242 | B18: FC | C18: 1) C def from low paste weight / Hi-C def from probe error. 2) LC def from over reject. | D18: 1) Check & Change probe 2) Improve paste printing op. | E18: PE | F18: On going
A19: 46240 | B19: FC | C19: Plate crack & terminal bending NG from plate inserting MC | D19: Adjust M/C for suitable cond. | E19: EE Mtnc. | F19: On going
A20: 46239 | B20: FC | C20: SD Def from tighten SD spec for expired element | D20: Review SD spec | E20: PE | F20: On going
A21: 46237 | B21: CAN | C21: 1)Outer case scratch from M/C | D21: Add sensor at inloader | E21: EE Eng. | F21: Not started
C22: 2)LC-SD defective from M/C | D22: Improve panel damage | E22: EE Mtnc. | F22: On going
A23: 46235 | B23: CAN | C23: C def from NG Probe | D23: Check probe & re-screen def(Unable to fix def in MES) | E23: PE/EE | F23: Done
D38: Target | G38: 46204 | J38: 46205 | M38: 46206 | P38: 46207 | S38: 46208 | V38: 46209 | Y38: 46210 | AB38: 46211 | AE38: 46212 | AH38: 46213 | AK38: 46214 | AN38: 46215 | AQ38: 46216 | AT38: 46217 | AW38: 46218 | AZ38: 46219 | BC38: 46220 | BF38: 46221 | BI38: 46222 | BL38: 46223 | BO38: 46224 | BR38: 46225 | BU38: 46226 | BX38: 46227 | CA38: 46228 | CD38: 46229 | CG38: 46230 | CJ38: 46231 | CM38: 46232 | CP38: 46233 | CS38: 46234 | CV38: MTD
B39: Sub | C39: Case | D39: %Yield | E39: Output (KP) | F39: Lot | G39: %Yield | H39: Output (KP) | I39: Lot | J39: %Yield | K39: Output (KP) | L39: Lot | M39: %Yield | N39: Output (KP) | O39: Lot | P39: %Yield | Q39: Output (KP) | R39: Lot | S39: %Yield | T39: Output (KP) | U39: Lot | V39: %Yield | W39: Output (KP) | X39: Lot | Y39: %Yield | Z39: Output (KP) | AA39: Lot | AB39: %Yield | AC39: Output (KP) | AD39: Lot | AE39: %Yield | AF39: Output (KP) | AG39: Lot | AH39: %Yield | AI39: Output (KP) | AJ39: Lot | AK39: %Yield | AL39: Output (KP) | AM39: Lot | AN39: %Yield | AO39: Output (KP) | AP39: Lot | AQ39: %Yield | AR39: Output (KP) | AS39: Lot | AT39: %Yield | AU39: Output (KP) | AV39: Lot | AW39: %Yield | AX39: Output (KP) | AY39: Lot | AZ39: %Yield | BA39: Output (KP) | BB39: Lot | BC39: %Yield | BD39: Output (KP) | BE39: Lot | BF39: %Yield | BG39: Output (KP) | BH39: Lot | BI39: %Yield | BJ39: Output (KP) | BK39: Lot | BL39: %Yield | BM39: Output (KP) | BN39: Lot | BO39: %Yield | BP39: Output (KP) | BQ39: Lot | BR39: %Yield | BS39: Output (KP) | BT39: Lot | BU39: %Yield | BV39: Output (KP) | BW39: Lot | BX39: %Yield | BY39: Output (KP) | BZ39: Lot | CA39: %Yield | CB39: Output (KP) | CC39: Lot | CD39: %Yield | CE39: Output (KP) | CF39: Lot | CG39: %Yield | CH39: Output (KP) | CI39: Lot | CJ39: %Yield | CK39: Output (KP) | CL39: Lot | CM39: %Yield | CN39: Output (KP) | CO39: Lot | CP39: %Yield | CQ39: Output (KP) | CR39: Lot | CS39: %Yield | CT39: Output (KP) | CU39: Lot | CV39: %Yield | CW39: Output (KP) | CX39: Lot | CY39: Diff with Target
A40: SC | B40: Can | D40: 98.45 | E40: 800 | F40: 148 | G40: 98.53 | H40: 39.619 | I40: 5 | J40: 98.32 | K40: 15.705 | L40: 4 | M40: 98.53 | N40: 18.073 | O40: 2 | P40: 98.55 | Q40: 17.508 | R40: 2 | S40: 99.11 | T40: 17.691 | U40: 3 | V40: 98.06 | W40: 5.958 | X40: 3 | Y40: 98.59 | Z40: 21.763 | AA40: 3 | AB40: 98.37 | AC40: 40.259 | AD40: 6 | AE40: 98.51 | AF40: 31.374 | AG40: 6 | AH40: 98.71 | AI40: 22.53 | AJ40: 3 | AK40: 98.56 | AL40: 83.5 | AM40: 2 | AN40: 98.91 | AO40: 13.846 | AP40: 3 | AQ40: 98.53 | AR40: 53.024 | AS40: 10 | AT40: 99.12 | AU40: =2026/1000 -> 2.026 | AV40: 1 | AW40: 98.01 | AX40: =37114/1000 -> 37.114 | AY40: 10 | AZ40: 97.54 | BA40: =34804/1000 -> 34.804 | BB40: 8 | BC40: 98.73 | BD40: =36398/1000 -> 36.398 | BE40: 7 | BF40: 99.18 | BG40: =21635/1000 -> 21.635 | BH40: 5 | BI40: 98.74 | BJ40: =27770/1000 -> 27.77 | BK40: 5 | BL40: 98.03 | BM40: =24441/1000 -> 24.441 | BN40: 9 | BO40: 97.22 | BP40: =46388/1000 -> 46.388 | BQ40: 8 | BR40: 96.68 | BS40: =78030/1000 -> 78.03 | BT40: 12 | BU40: 98.43 | BV40: =50782/1000 -> 50.782 | BW40: 8 | BX40: 98.95 | BY40: =23929/1000 -> 23.929 | BZ40: 6 | CA40: 98.93 | CB40: =39320/1000 -> 39.32 | CC40: 5 | CD40: 98.99 | CE40: =38110/1000 -> 38.11 | CF40: 4 | CG40: 98.91 | CH40: =25241/1000 -> 25.241 | CI40: 4 | CJ40: 98.65 | CK40: =32513/1000 -> 32.513 | CL40: 4 | CM40: 98.26 | CN40: =47228/1000 -> 47.228 | CO40: 6 | CV40: =AVERAGE(G40,J40,M40,P40,S40,V40,Y40,AB40,AE40,AH40,AK40,AN40,AQ40,AT40,AW40,AZ40,BC40,BF40,BI40,BL40,BO40,BR40,BU40,BX40,CA40,CD40,CG40,CJ40,CM40,CP40,CS40) -> 98.47069 | CW40: =SUM(H40,K40,N40,Q40,T40,W40,Z40,AC40,AF40,AI40,AL40,AO40,AR40,AU40,AX40,BA40,BD40,BG40,BJ40,BM40,BP40,BS40,BV40,BY40,CB40,CE40,CH40,CK40,CN40,CQ40,CT40) -> 946.579 | CX40: =SUM(I40,L40,O40,R40,U40,X40,AA40,AD40,AG40,AJ40,AM40,AP40,AS40,AV40,AY40,BB40,BE40,BH40,BK40,BN40,BQ40,BT40,BW40,BZ40,CC40,CF40,CI40,CL40,CO40,CR40,CU40) -> 154 | CY40: =CV40-D40 -> 0.020689655
A41: (End Prod) | B41: FC | D41: 99.1 | E41: 1550.0003 | F41: 117 | G41: 99.41 | H41: 38 | I41: 3 | J41: 99.61 | K41: 31.5 | L41: 2 | M41: 99.45 | N41: 37.5 | O41: 3 | P41: 99.28 | Q41: 55.5 | R41: 4 | S41: 99.42 | T41: 51 | U41: 4 | V41: 99.19 | W41: 38 | X41: 3 | Y41: 99.3 | Z41: 73 | AA41: 6 | AB41: 99.28 | AC41: 75 | AD41: 6 | AE41: 99.37 | AF41: 44.5 | AG41: 3 | AH41: 99.57 | AI41: 76.5 | AJ41: 5 | AK41: 99.24 | AL41: 48.95 | AM41: 4 | AN41: 99.02 | AO41: 63.4 | AP41: 5 | AQ41: 98.69 | AR41: 72.6 | AS41: 5 | AT41: 99.46 | AU41: =30500/1000 -> 30.5 | AV41: 2 | AW41: 99.45 | AX41: =44000/1000 -> 44 | AY41: 3 | AZ41: 99.09 | BA41: =50300/1000 -> 50.3 | BB41: 4 | BC41: 99.71 | BD41: =38000/1000 -> 38 | BE41: 2 | BF41: 99.3 | BG41: =19000/1000 -> 19 | BH41: 1 | BI41: 99.73 | BJ41: =37000/1000 -> 37 | BK41: 2 | BL41: 99.32 | BM41: =13000/1000 -> 13 | BN41: 1 | BO41: 99.6 | BP41: =31000/1000 -> 31 | BQ41: 2 | BR41: 99.68 | BS41: =19000/1000 -> 19 | BT41: 2 | BU41: 99.62 | BV41: =33000/1000 -> 33 | BW41: 2 | BX41: 99.43 | BY41: =51000/1000 -> 51 | BZ41: 5 | CA41: 99.36 | CB41: =45000/1000 -> 45 | CC41: 3 | CD41: 99.42 | CE41: =63500/1000 -> 63.5 | CF41: 5 | CG41: 98.77 | CH41: =30000/1000 -> 30 | CI41: 3 | CJ41: 99.5 | CK41: =37500/1000 -> 37.5 | CL41: 3 | CM41: 96.32 | CN41: =93000/1000 -> 93 | CO41: 8 | CV41: =AVERAGE(G41,J41,M41,P41,S41,V41,Y41,AB41,AE41,AH41,AK41,AN41,AQ41,AT41,AW41,AZ41,BC41,BF41,BI41,BL41,BO41,BR41,BU41,BX41,CA41,CD41,CG41,CJ41,CM41,CP41,CS41) -> 99.261724 | CW41: =SUM(H41,K41,N41,Q41,T41,W41,Z41,AC41,AF41,AI41,AL41,AO41,AR41,AU41,AX41,BA41,BD41,BG41,BJ41,BM41,BP41,BS41,BV41,BY41,CB41,CE41,CH41,CK41,CN41,CQ41,CT41) -> 1340.25 | CX41: =SUM(I41,L41,O41,R41,U41,X41,AA41,AD41,AG41,AJ41,AM41,AP41,AS41,AV41,AY41,BB41,BE41,BH41,BK41,BN41,BQ41,BT41,BW41,BZ41,CC41,CF41,CI41,CL41,CO41,CR41,CU41) -> 101 | CY41: =CV41-D41 -> 0.16172414
B42: FM | D42: 99.2 | E42: 1200 | F42: 94 | G42: 99.53 | H42: 17 | I42: 1 | J42: 99.51 | K42: 22 | L42: 2 | M42: 98.78 | N42: 18.927 | O42: 2 | P42: 99.7 | Q42: 33 | R42: 2 | S42: 99.62 | T42: 63.134 | U42: 4 | V42: 99.51 | W42: 46 | X42: 3 | Y42: 99.63 | Z42: 68.99 | AA42: 6 | AB42: 99.56 | AC42: 66.356 | AD42: 5 | AE42: 99.56 | AF42: 50.151 | AG42: 5 | AH42: 99.58 | AI42: 65.2 | AJ42: 5 | AK42: 99.49 | AL42: 38 | AM42: 3 | AN42: 99.39 | AO42: 80.744 | AP42: 6 | AQ42: 99.35 | AR42: 55.464 | AS42: 6 | AT42: 99.38 | AU42: =24665/1000 -> 24.665 | AV42: 2 | AW42: 99.26 | AX42: =38000/1000 -> 38 | AY42: 3 | AZ42: 99.68 | BA42: =12644/1000 -> 12.644 | BB42: 1 | BD42: 0 | BE42: 0 | BG42: 0 | BH42: 0 | BI42: 99.63 | BJ42: =37000/1000 -> 37 | BK42: 2 | BL42: 99.45 | BM42: =23800/1000 -> 23.8 | BN42: 2 | BO42: 99.65 | BP42: =37000/1000 -> 37 | BQ42: 2 | BR42: 99.72 | BS42: =25000/1000 -> 25 | BT42: 1 | BU42: 99.71 | BV42: =57000/1000 -> 57 | BW42: 4 | BX42: 99.65 | BY42: =86399/1000 -> 86.399 | BZ42: 7 | CA42: 99.64 | CB42: =49389/1000 -> 49.389 | CC42: 5 | CD42: 99.48 | CE42: =13000/1000 -> 13 | CF42: 1 | CG42: 99.8 | CH42: =38000/1000 -> 38 | CI42: 2 | CK42: 0 | CL42: 0 | CM42: 99.65 | CN42: =17090/1000 -> 17.09 | CO42: 1 | CV42: =AVERAGE(G42,J42,M42,P42,S42,V42,Y42,AB42,AE42,AH42,AK42,AN42,AQ42,AT42,AW42,AZ42,BC42,BF42,BI42,BL42,BO42,BR42,BU42,BX42,CA42,CD42,CG42,CJ42,CM42,CP42,CS42) -> 99.535 | CW42: =SUM(H42,K42,N42,Q42,T42,W42,Z42,AC42,AF42,AI42,AL42,AO42,AR42,AU42,AX42,BA42,BD42,BG42,BJ42,BM42,BP42,BS42,BV42,BY42,CB42,CE42,CH42,CK42,CN42,CQ42,CT42) -> 1083.953 | CX42: =SUM(I42,L42,O42,R42,U42,X42,AA42,AD42,AG42,AJ42,AM42,AP42,AS42,AV42,AY42,BB42,BE42,BH42,BK42,BN42,BQ42,BT42,BW42,BZ42,CC42,CF42,CI42,CL42,CO42,CR42,CU42) -> 83 | CY42: =CV42-D42 -> 0.335
B43: Grand Total | D43: 99 | E43: =SUM(E40:E42) -> 3550.0003 | F43: =SUM(F40:F42) -> 359 | G43: =(G40*H40/H43)+(G41*H41/H43)+(G42*H42/H43) -> 99.063085 | H43: =SUM(H40:H42) -> 94.619 | I43: =SUM(I40:I42) -> 9 | J43: =(J40*K40/K43)+(J41*K41/K43)+(J42*K42/K43) -> 99.285465 | K43: =SUM(K40:K42) -> 69.205 | L43: =SUM(L40:L42) -> 8 | M43: =(M40*N40/N43)+(M41*N41/N43)+(M42*N42/N43) -> 99.056601 | N43: =SUM(N40:N42) -> 74.5 | O43: =SUM(O40:O42) -> 7 | P43: =(P40*Q40/Q43)+(P41*Q41/Q43)+(P42*Q42/Q43) -> 99.29018 | Q43: =SUM(Q40:Q42) -> 106.008 | R43: =SUM(R40:R42) -> 8 | S43: =(S40*T40/T43)+(S41*T41/T43)+(S42*T42/T43) -> 99.474182 | T43: =SUM(T40:T42) -> 131.825 | U43: =SUM(U40:U42) -> 11 | V43: =(V40*W40/W43)+(V41*W41/W43)+(V42*W42/W43) -> 99.278791 | W43: =SUM(W40:W42) -> 89.958 | X43: =SUM(X40:X42) -> 9 | Y43: =(Y40*Z40/Z43)+(Y41*Z41/Z43)+(Y42*Z42/Z43) -> 99.344671 | Z43: =SUM(Z40:Z42) -> 163.753 | AA43: =SUM(AA40:AA42) -> 15 | AB43: =(AB40*AC40/AC43)+(AB41*AC41/AC43)+(AB42*AC42/AC43) -> 99.180581 | AC43: =SUM(AC40:AC42) -> 181.615 | AD43: =SUM(AD40:AD42) -> 17 | AE43: =(AE40*AF40/AF43)+(AE41*AF41/AF43)+(AE42*AF42/AF43) -> 99.231512 | AF43: =SUM(AF40:AF42) -> 126.025 | AG43: =SUM(AG40:AG42) -> 14 | AH43: =(AH40*AI40/AI43)+(AH41*AI41/AI43)+(AH42*AI42/AI43) -> 99.45599 | AI43: =SUM(AI40:AI42) -> 164.23 | AJ43: =SUM(AJ40:AJ42) -> 13 | AK43: =(AK40*AL40/AL43)+(AK41*AL41/AL43)+(AK42*AL42/AL43) -> 98.962617 | AL43: =SUM(AL40:AL42) -> 170.45 | AM43: =SUM(AM40:AM42) -> 9 | AN43: =(AN40*AO40/AO43)+(AN41*AO41/AO43)+(AN42*AO42/AO43) -> 99.199456 | AO43: =SUM(AO40:AO42) -> 157.99 | AP43: =SUM(AP40:AP42) -> 14 | AQ43: =(AQ40*AR40/AR43)+(AQ41*AR41/AR43)+(AQ42*AR42/AR43) -> 98.845297 | AR43: 181.088 | AS43: 21 | AT43: =(AT40*AU40/AU43)+(AT41*AU41/AU43)+(AT42*AU42/AU43) -> 99.413454 | AU43: =SUM(AU40:AU42) -> 57.191 | AV43: =SUM(AV40:AV42) -> 5 | AW43: =(AW40*AX40/AX43)+(AW41*AX41/AX43)+(AW42*AX42/AX43) -> 98.940705 | AX43: =SUM(AX40:AX42) -> 119.114 | AY43: =SUM(AY40:AY42) -> 16 | AZ43: =(AZ40*BA40/BA43)+(AZ41*BA41/BA43)+(AZ42*BA42/BA43) -> 98.614428 | BA43: =SUM(BA40:BA42) -> 97.748 | BB43: =SUM(BB40:BB42) -> 13 | BC43: =(BC40*BD40/BD43)+(BC41*BD41/BD43)+(BC42*BD42/BD43) -> 99.230551 | BD43: =SUM(BD40:BD42) -> 74.398 | BE43: =SUM(BE40:BE42) -> 9 | BF43: =(BF40*BG40/BG43)+(BF41*BG41/BG43)+(BF42*BG42/BG43) -> 99.236109 | BG43: =SUM(BG40:BG42) -> 40.635 | BH43: =SUM(BH40:BH42) -> 6 | BI43: =(BI40*BJ40/BJ43)+(BI41*BJ41/BJ43)+(BI42*BJ42/BJ43) -> 99.423502 | BJ43: =SUM(BJ40:BJ42) -> 101.77 | BK43: =SUM(BK40:BK42) -> 9 | BL43: =(BL40*BM40/BM43)+(BL41*BM41/BM43)+(BL42*BM42/BM43) -> 98.855689 | BM43: =SUM(BM40:BM42) -> 61.241 | BN43: =SUM(BN40:BN42) -> 12 | BO43: =(BO40*BP40/BP43)+(BO41*BP41/BP43)+(BO42*BP42/BP43) -> 98.651007 | BP43: =SUM(BP40:BP42) -> 114.388 | BQ43: =SUM(BQ40:BQ42) -> 12 | BR43: =(BR40*BS40/BS43)+(BR41*BS41/BS43)+(BR42*BS42/BS43) -> 97.769896 | BS43: =SUM(BS40:BS42) -> 122.03 | BT43: =SUM(BT40:BT42) -> 15 | BU43: =(BU40*BV40/BV43)+(BU41*BV41/BV43)+(BU42*BV42/BV43) -> 99.22719 | BV43: =SUM(BV40:BV42) -> 140.782 | BW43: =SUM(BW40:BW42) -> 14 | CV43: =(CV40*CW40/CW43)+(CV41*CW41/CW43)+(CV42*CW42/CW43) -> 99.127465 | CW43: =SUM(CW40:CW42) -> 3370.782 | CX43: =SUM(CX40:CX42) -> 338 | CY43: =CV43-D43 -> 0.12746495
A49: Date | B49: Series | C49: Problem | D49: Action | E49: PIC | F49: Progress
A50: 46218 | B50: CAN | C50: 1)LC-SD defective from M/C (Big size product ->Less lot size-higher impact) | D50: Improve panel damage | E50: EE Mtnc. | F50: On going
C51: 2)Outer case scratch from M/C | D51: Add sensor at inloader | E51: EE Eng. | F51: Not started
A52: 46219 | B52: CAN | C52: 1)LC-SD defective from M/C (Big size product ->Less lot size-higher impact) | D52: Improve panel damage | E52: EE Mtnc. | F52: On going
B53: FC | C53: LC-SD defective ->Big size operate in CAN line | D53: Improve panel damage | E53: EE Mtnc. | F53: On going
A54: 46223 | B54: CAN | C54: 1)LC-SD defective from M/C (Big size product ->Less lot size-higher impact) | D54: Improve panel damage | E54: EE Mtnc. | F54: On going
A55: 46224 | B55: CAN | C55: LC-SD defective -> Re-screen liq-leak many round for expired element which is MFG in problem period previous year. | D55: Keep check & control process | E55: PE | F55: On going
A56: 46225 | B56: CAN | C56: C defective 17MUF -> Low paste printing (Element stock before action) | D56: Add check item & trouble shooting for printing & combine operation. | E56: PE | F56: Done
A57: 46226 | B57: FC | C57: C def 8LCRF -> New Product design problem | D57: Under improvement with Tech. | E57: PE | F57: On going
A58: 46232 | B58: CAN | C58: 1)Outer case scratch from M/C | D58: Add sensor at inloader | E58: EE Eng. | F58: Not started
B59: FC | C59: 1) Wrong input defective q'ty in MES. | D59: Feedback to Prod. | E59: PE | F59: On going
