Workbook

Sheet Prod vol-Ship
D1: Start date | E1: 46204
B2: Prod Vol (Output-KP) | D2: Today | E2: =TODAY() -> 46258 | F2: =DAY(E2-E1) -> 23
B3: Process | C3: Series/Case | D3: Jul'26 Target | E3: Daily Goal | F3: MTD Goal | G3: MTD | H3: Pace | I3: Performance MTD
A4: TaPoly | B4: TET's anode | C4: All | D4: 28964 | E4: 965.46667 | F4: 9654.6667 | G4: 12733 | H4: =G4-F4 -> 3078.3333 | I4: =G4/F4 -> 1.3188441
B5: Racking | C5: All | D5: 176522.52 | E5: 5884.084 | F5: 58840.84 | G5: 74100.9 | H5: =G5-F5 -> 15260.06 | I5: =G5/F5 -> 1.2593447
B6: BOL (Silver) | C6: PSLA | D6: 9552.2867 | E6: 318.40956 | F6: 3184.0956 | G6: 3828.401 | H6: =G6-F6 -> 644.30545 | I6: =G6/F6 -> 1.2023512
C7: PSLB | D7: 132957.06 | E7: 4431.9018 | F7: 44319.018 | G7: 54800.263 | H7: =G7-F7 -> 10481.245 | I7: =G7/F7 -> 1.2364954
C8: FPSA | D8: 18639.959 | E8: 621.33198 | F8: 6213.3198 | G8: 9114.193 | H8: =G8-F8 -> 2900.8732 | I8: =G8/F8 -> 1.4668797
C9: FPSB | D9: 10361.348 | E9: 345.37828 | F9: 3453.7828 | G9: 4438.272 | H9: =G9-F9 -> 984.48917 | I9: =G9/F9 -> 1.2850466
C10: GPSP2 | D10: 3963.1937 | E10: 132.10646 | F10: 1321.0646 | G10: 1726.75 | H10: =G10-F10 -> 405.68544 | I10: =G10/F10 -> 1.3070898
C11: Total | D11: 175473.84 | E11: 5849.1281 | F11: 58491.281 | G11: 73907.879 | H11: =SUM(H6:H10) -> 15416.598 | I11: =G11/F11 -> 1.2635709
B12: EOL (E/I) | C12: PSLA | D12: 8600 | E12: 286.66667 | F12: 2866.6667 | G12: 3818 | H12: =G12-F12 -> 951.33333 | I12: =G12/F12 -> 1.3318605
C13: PSLB | D13: 120794.95 | E13: 4026.4983 | F13: 40264.983 | G13: 51107 | H13: =G13-F13 -> 10842.017 | I13: =G13/F13 -> 1.2692666
C14: FPSA | D14: 15200 | E14: 506.66667 | F14: 5066.6667 | G14: 5775 | H14: =G14-F14 -> 708.33333 | I14: =G14/F14 -> 1.1398026
C15: FPSB | D15: 8900 | E15: 296.66667 | F15: 2966.6667 | G15: 4224 | H15: =G15-F15 -> 1257.3333 | I15: =G15/F15 -> 1.4238202
C16: GPSP2 | D16: 3200 | E16: 106.66667 | F16: 1066.6667 | G16: 1323 | H16: =G16-F16 -> 256.33333 | I16: =G16/F16 -> 1.2403125
C17: Total | D17: 156694.95 | E17: 5223.165 | F17: 52231.65 | G17: 66247 | H17: =SUM(H12:H16) -> 14015.35 | I17: =G17/F17 -> 1.2683306
B18: Final (901) | C18: PSLA | D18: 8600 | E18: =D18/30 -> 286.66667 | F18: =E18*$F$2 -> 6593.3333 | G18: =SUM('[1]Output_Jul''26'!$Q$49) -> 3886 | H18: =G18-F18 -> -2707.3333 | I18: =G18/F18 -> 0.58938322
C19: PSLB | D19: 120000 | E19: =D19/30 -> 4000 | F19: =E19*$F$2 -> 92000 | G19: =SUM('[1]Output_Jul''26'!$Q$50:$Q$55) -> 51374 | H19: =G19-F19 -> -40626 | I19: =G19/F19 -> 0.55841304
C20: FPSA | D20: 15200 | E20: =D20/30 -> 506.66667 | F20: =E20*$F$2 -> 11653.333 | G20: =SUM('[1]Output_Jul''26'!$Q$56:$Q$59,'[1]Output_Jul''26'!$Q$63) -> 4956 | H20: =G20-F20 -> -6697.3333 | I20: =G20/F20 -> 0.42528604
C21: FPSB | D21: 8900 | E21: =D21/30 -> 296.66667 | F21: =E21*$F$2 -> 6823.3333 | G21: =SUM('[1]Output_Jul''26'!$Q$60:$Q$61) -> 4005 | H21: =G21-F21 -> -2818.3333 | I21: =G21/F21 -> 0.58695652
C22: GPSP2 | D22: 3200 | E22: =D22/30 -> 106.66667 | F22: =E22*$F$2 -> 2453.3333 | G22: ='[1]Output_Jul''26'!$Q$62 -> 1140 | H22: =G22-F22 -> -1313.3333 | I22: =G22/F22 -> 0.46467391
C23: Total | D23: =SUM(D18:D22) -> 155900 | E23: =SUM(E18:E22) -> 5196.6667 | F23: =SUM(F18:F22) -> 119523.33 | G23: =SUM(G18:G22) -> 65361 | H23: =G23-F23 -> -54162.333 | I23: =G23/F23 -> 0.5468472
A24: SC | B24: Can | D24: 800 | E24: =D24/30 -> 26.666667 | F24: =E24*$F$2 -> 613.33333 | G24: 437.258 | H24: =G24-F24 -> -176.07533 | I24: =G24/F24 -> 0.71292065
B25: FC | D25: 1550.0003 | E25: =D25/30 -> 51.666678 | F25: =E25*$F$2 -> 1188.3336 | G25: 838 | H25: =G25-F25 -> -350.3336 | I25: =G25/F25 -> 0.70518918
B26: FM | D26: 1200 | E26: =D26/30 -> 40 | F26: =E26*$F$2 -> 920 | G26: 792.2 | H26: =G26-F26 -> -127.8 | I26: =G26/F26 -> 0.86108696
B27: TTL FG | D27: =SUM(D24:D26) -> 3550.0003 | E27: =D27/30 -> 118.33334 | F27: =E27*$F$2 -> 2721.6669 | G27: =SUM(G24:G26) -> 2067.458 | H27: =G27-F27 -> -654.20893 | I27: =G27/F27 -> 0.75962932
B31: Shipping (KP)
C32: Series/Case | D32: Jul'26 Target | E32: Daily Goal | F32: MTD Goal | G32: MTD | H32: Pace | I32: Performance MTD
A33: TaPoly | C33: PSL+PSG | D33: 113208 | F33: =SUM('[1]Ship_Jul''26'!$D$4:$Q$4) -> 30112 | G33: =SUM('[1]Ship_Jul''26'!$D$9:$Q$9) -> 35935 | H33: =G33-F33 -> 5823 | I33: =G33/F33 -> 1.1933781
C34: FPS+FPU | D34: 18057 | F34: =SUM('[1]Ship_Jul''26'!$D$5:$Q$5) -> 7959 | G34: =SUM('[1]Ship_Jul''26'!$D$10:$Q$10) -> 8130 | H34: =G34-F34 -> 171 | I34: =G34/F34 -> 1.0214851
C35: GPS | D35: 3138 | F35: =SUM('[1]Ship_Jul''26'!$D$6:$Q$6) -> 1158 | G35: =SUM('[1]Ship_Jul''26'!$D$11:$Q$11) -> 1266 | H35: =G35-F35 -> 108 | I35: =G35/F35 -> 1.0932642
C36: TTL | D36: =SUM(D33:D35) -> 134403 | F36: =SUM(F33:F35) -> 39229 | G36: =SUM(G33:G35) -> 45331 | H36: =G36-F36 -> 6102 | I36: =G36/F36 -> 1.1555482
A37: SC | C37: Can | D37: 797.63 | F37: =SUM('[1]Ship_Jul''26'!$D$16:$Q$16) -> 337.26 | G37: ='[1]Ship_Jul''26'!$C$21 -> 470.66 | H37: =G37-F37 -> 133.4 | I37: =G37/F37 -> 1.3955405
C38: FC | D38: 1552.4 | F38: =SUM('[1]Ship_Jul''26'!$D$17:$Q$17) -> 256.15 | G38: ='[1]Ship_Jul''26'!$C$22 -> 531.8 | H38: =G38-F38 -> 275.65 | I38: =G38/F38 -> 2.0761273
C39: FM | D39: 1185.3 | F39: =SUM('[1]Ship_Jul''26'!$D$18:$Q$18) -> 671 | G39: ='[1]Ship_Jul''26'!$C$23 -> 1006 | H39: =G39-F39 -> 335 | I39: =G39/F39 -> 1.4992548
C40: TTL | D40: =SUM(D37:D39) -> 3535.33 | F40: =SUM(F37:F39) -> 1264.41 | G40: =SUM(G37:G39) -> 2008.46 | H40: =G40-F40 -> 744.05 | I40: =G40/F40 -> 1.5884563

Sheet Daily_Yield_Ta
A34: Date | B34: Series | C34: Problem | D34: Analysis/ Action | G34: PIC | I34: Progress | P34: Due Date
A35: 46254 | B35: FPSA08 (A081C226) | C35: In-process-DW CAM3 Dimension CAM2 Mold-chip | D35: CAM-3 defect occurrence appears to be related to both the dicing process and the Pick & Place (P&P) machine. A significant difference in defect levels has been observed among machines, with some showing normal performance while others exhibit considerably higher defect rates. LC shift at ACC is a reversible heat and moisture effect, not permanent dielectric damage. The recovery after M-Treatment confirms that the change is temporary and moisture-related. SMT LC shift is a reversible thermal/moisture-related phenomenon rather than permanent degradation. | G35: Ms. Sasitorn Ms. Chotmanee | I35: CAM3 (1) Dicing Blade : Check material properties / Material setting before start operate Dicing process (2) Further investigation is required to identify the specific machine conditions and mechanisms contributing to the variation. (3) Unnder prepare exp. trial new spec L dimension (change mean from 3.35 to 3.2 mm.) | P35: 46252
B36: PSGB2 (B20E337) | C36: ESR | D36: ESR was high deviation in some lot, PSGB2 was high sensivity. (1) From analysis found polymer had black spot at internal polymer that means inner is not cover well (2)Another is insulate of polymer was not get good insulatuin peak so LC high & get ESR high also. | G36: Ms. Supatsara Ms. Paemika Ms. Kanlaya | I36: (1)Apperance by polymer step was variation via blister, under investigate & improve blister in in situ. -For reduceSYOx on internal polymer to reduce deviation of ESR,QOD change, under evaluation test (2)Insulation effect conduct of QOD change re-anodization pattern LI to CR, get result 30 lot. Good result for LC and ESR deviation was improve. Under go to implement&verification step. | P36: 46276
B37: PSLB2 (B21A107) (B20J227) | C37: App : Terminal Red | D37: From Analysis data -Gule mixing condition was not good (A&B) was not mix well -Consider another factor | G37: Ms. Supatsara Ms. Chantira Mr. Nonthawat | I37: -Finished experiment Mazerustar mixing machine, get good result for homogenous -Trial on 13 Aug,26 on 2HD(FA8) welding machine 3 lots, get good result, can reduce defect. Already summary, will make discuss how to apply & will set operation method | P37: 46254
B38: PSLB15 | C38: Terminal red B150J227M | D38: Partial apply reduce glue quantity 25mg to 15mg (QOD plan within 21-Aug) | G38: TE (NPD) Mr. Suwicha Ms. Narakorn | I38: Defective was low ratio, TE under conclude the result | P38: 46255
A39: 46252 | B39: FPSA08 (A081C226) | C39: In-process-DW CAM3 Dimension CAM2 Mold-chip | D39: CAM3 P&P F10 has high deviation, after review actual L dimension are nearly to upper spec. The improvement is (1) Review appropriate specification by matching with actual process capability and catalog (2) Minimize process deviation by control setting machine and material | G39: Ms. Sasitorn C. Ms. Chotmanee P. | I39: CAM-3 : Further investigation is required to identify the specific machine conditions and mechanisms contributing to the variation.
B40: PSGB2 (B20E337) | C40: ESR | D40: ESR was high deviation in some lot, PSGB2 was high sensivity. (1) From analysis found polymer had black spot at internal polymer that means inner is not cover well (2)Another is insulate of polymer was not get good insulatuin peak so LC high & get ESR high also. | G40: Ms. Supatsara Ms. Paemika Ms. Kanlaya | I40: First, conduct a detailed analysis to identify the process factors contributing to the ESR differences between the low ESR and high ESR groups, and determine the key parameters driving the variation | P40: 46255
B41: PSLB2 (B20J107) (B20J227) | C41: App : Terminal Red | D41: From Analysis data -Gule mixing condition was not good (A&B) was not mix well -Consider another factor | G41: Ms. Supatsara Ms. Chantira Mr. Nonthawat | I41: -Finished experiment Mazerustar mixing machine, get good result for homogenous -Trial on 13 Aug,26 on 2HD(FA8) welding machine 3 lots, get good result, can reduce defect. Already summary, will make discuss how to apply & will set operation method | P41: 46254
B42: PSLB15 | C42: Terminal red B150J227M | D42: Partial apply reduce glue quantity 25mg to 15mg (QOD plan within 21-Aug) | G42: TE (NPD) Mr. Suwicha Ms. Narakorn | I42: Defective was low ratio, TE under conclude the result | P42: 46255
A43: 46251 | B43: FPSA3 (A30J107) | C43: ESR Problem from L/F lot and Problems beyond L/F. Inprocess-DW CAM3 Dimension | D43: ESR : Remaining WIP for L/F problem = 6 Lots Problems beyond L/F. --> Focus to Mold clamp. CAM-3 defect occurrence appears to be related to both the dicing process and the Pick & Place (P&P) machine. A significant difference in defect levels has been observed among machines, with some showing normal performance while others exhibit considerably higher defect rates. | G43: Mr. Jirapat Mr. Pawekorn | I43: ESR '1. Feedback to supplier about L/F dimension. 2. Standardize L/F dimensional control to reduce ESR variation. | P43: 46248
B44: FPSA08 (A081C226) | C44: In-process-DW CAM3 Dimension CAM2 Mold-chip | D44: CAM-3 defect occurrence appears to be related to both the dicing process and the Pick & Place (P&P) machine. A significant difference in defect levels has been observed among machines, with some showing normal performance while others exhibit considerably higher defect rates. LC shift at ACC is a reversible heat and moisture effect, not permanent dielectric damage. The recovery after M-Treatment confirms that the change is temporary and moisture-related. SMT LC shift is a reversible thermal/moisture-related phenomenon rather than permanent degradation. | G44: Ms. Sasitorn Ms. Chotmanee | I44: CAM-3 : Further investigation is required to identify the specific machine conditions and mechanisms contributing to the variation. ACC/SMT - Temporary Action: Optimize moisture control during ACC/SMT to minimize the reversible LC shift. - Permanent Action: Identify and eliminate the root cause at ACC by improving dielectric uniformity and stability. | P44: 46252
B45: PSGB2 (B20E337) | C45: ESR Blister: Conveyer machine make bubble of GB2,B2 | D45: ESR was high deviation in some lot, PSGB2 was high sensivity. (1) From analysis found polymer had black spot at internal polymer that means inner is not cover well (2)Another is insulate of polymer was not get good insulatuin peak so LC high & get ESR high also. Blister : Conveyer had high temp & low hu at machine no Z1, EE BOL already fix it & GB2 case specify to not apply this machine (shape of anode were effect to blister). | G45: Ms. Supatsara Ms. Paemika Ms. Kanlaya | I45: First, conduct a detailed analysis to identify the process factors contributing to the ESR differences between the low ESR and high ESR groups, and determine the key parameters driving the variation We are currently investigating potential blister formation associated with abnormalities in the NR conveyor of the Z1 equipment. The objective is to clarify the blister formation mechanism, identify the root cause, and implement permanent corrective actions to prevent recurrence. | P45: 46255
B46: PSLB2 (B20J107) (B20J227) | C46: App : Terminal Red | D46: From Analysis data -Gule mixing condition was not good (A&B) was not mix well -Consider another factor | G46: Ms. Supatsara Ms. Chantira Mr. Nonthawat | I46: -Finished experiment Mazerustar mixing machine, get good result for homogenous -Trial on 13 Aug,26 on 2HD(FA8) welding machine 3 lots, wait for result > Get good result but still deviation (1 lot still high def.), under conclude result > Finished E/I on Aug 18 | P46: 46254
B47: PSLB15 | C47: Terminal red B150J227M | D47: Partial apply reduce glue quantity 25mg to 15mg (QOD plan within 21-Aug) | G47: TE (NPD) Mr. Suwicha Ms. Narakorn | I47: Defective was low ratio, TE under conclude the result | P47: 46255
A48: 46250 | B48: FPSA3 (A30J107) | C48: ESR Problem from L/F lot and Problems beyond L/F. Inprocess-DW CAM3 Dimension | D48: ESR : Remaining WIP for L/F problem = 6 Lots Problems beyond L/F. --> Focus to Mold clamp. CAM-3 defect occurrence appears to be related to both the dicing process and the Pick & Place (P&P) machine. A significant difference in defect levels has been observed among machines, with some showing normal performance while others exhibit considerably higher defect rates. | G48: Mr. Jirapat Mr. Pawekorn | I48: ESR '1. Feedback to supplier about L/F dimension. 2. Standardize L/F dimensional control to reduce ESR variation. | P48: 46248
B49: FPSA08 (A081C226) | C49: In-process-DW CAM3 Dimension CAM2 Mold-chip | D49: CAM-3 defect occurrence appears to be related to both the dicing process and the Pick & Place (P&P) machine. A significant difference in defect levels has been observed among machines, with some showing normal performance while others exhibit considerably higher defect rates. LC shift at ACC is a reversible heat and moisture effect, not permanent dielectric damage. The recovery after M-Treatment confirms that the change is temporary and moisture-related. SMT LC shift is a reversible thermal/moisture-related phenomenon rather than permanent degradation. | G49: Ms. Sasitorn Ms. Chotmanee | I49: CAM-3 : Further investigation is required to identify the specific machine conditions and mechanisms contributing to the variation. ACC/SMT - Temporary Action: Optimize moisture control during ACC/SMT to minimize the reversible LC shift. - Permanent Action: Identify and eliminate the root cause at ACC by improving dielectric uniformity and stability. | P49: 46252
B50: PSGB2 (B20E337) | C50: ESR Blister: Conveyer machine make bubble of GB2,B2 | D50: ESR was high deviation in some lot, PSGB2 was high sensivity. (1) From analysis found polymer had black spot at internal polymer that means inner is not cover well (2)Another is insulate of polymer was not get good insulatuin peak so LC high & get ESR high also. Blister : Conveyer had high temp & low hu at machine no Z1, EE BOL already fix it & GB2 case specify to not apply this machine (shape of anode were effect to blister). | G50: Ms. Supatsara Ms. Paemika Ms. Kanlaya | I50: First, conduct a detailed analysis to identify the process factors contributing to the ESR differences between the low ESR and high ESR groups, and determine the key parameters driving the variation We are currently investigating potential blister formation associated with abnormalities in the NR conveyor of the Z1 equipment. The objective is to clarify the blister formation mechanism, identify the root cause, and implement permanent corrective actions to prevent recurrence. | P50: 46255
B51: PSLB2 (B20E477) | C51: ESR High powder grade LC Weak at welding machine | D51: ESR level and variability increased after 250KCV implementation. However, the presence of both good and bad lots suggests that process variation remains, requiring further investigation to identify and eliminate the sources of inconsistency LC --> check LC tendency by M/C and LC before/after welding HS6 Check history of changing of welding machine | G51: Ms. Supatsara Ms. Paemika Ms. Kanlaya | I51: First, conduct a detailed analysis to identify the process factors contributing to the ESR differences between the low ESR and high ESR groups, and determine the key parameters driving the variation QOD to improve LC by change M-Aging volt from 2.5 to 5V (Today Aug 13'26 apply 3 lot of change review) -->Initial result at E/I can not get yield improve, under conclude data | P51: E/Aug'26
B52: PSLB2 (B20J107) (B20J227) (B21A107) (B21C336) | C52: App : Terminal Red | D52: From Analysis data -Gule mixing condition was not good (A&B) was not mix well -Consider another factor | G52: Ms. Supatsara Ms. Chantira Mr. Nonthawat | I52: -Finished experiment Mazerustar mixing machine, get good result for homogenous -Trial on 13 Aug,26 on 2HD(FA8) welding machine 3 lots, wait for result > Get good result but still deviation (1 lot still high def.), under conclude result | P52: 46248
B53: PSLB15 | C53: Terminal red B150J227M | D53: Partial apply reduce glue quantity 25mg to 15mg (QOD plan within 21-Aug) | G53: TE (NPD) Mr. Suwicha Ms. Narakorn | I53: Defective was low ratio, TE under conclude the result | P53: 46255
A54: 46247 | B54: FPSA3 (A30J107) | C54: ESR Problem from L/F lot and Problems beyond L/F. Inprocess-DW CAM3 Dimension | D54: ESR : Remaining WIP for L/F problem = 6 Lots Problems beyond L/F. --> Focus to Mold clamp. CAM-3 defect occurrence appears to be related to both the dicing process and the Pick & Place (P&P) machine. A significant difference in defect levels has been observed among machines, with some showing normal performance while others exhibit considerably higher defect rates. | G54: Mr. Jirapat Mr. Pawekorn | I54: ESR '1. Feedback to supplier about L/F dimension. 2. Standardize L/F dimensional control to reduce ESR variation. | P54: 46248
B55: FPSA08 (A081C226) | C55: In-process-DW CAM3 Dimension CAM2 Mold-chip | D55: CAM-3 defect occurrence appears to be related to both the dicing process and the Pick & Place (P&P) machine. A significant difference in defect levels has been observed among machines, with some showing normal performance while others exhibit considerably higher defect rates. LC shift at ACC is a reversible heat and moisture effect, not permanent dielectric damage. The recovery after M-Treatment confirms that the change is temporary and moisture-related. SMT LC shift is a reversible thermal/moisture-related phenomenon rather than permanent degradation. | G55: Ms. Sasitorn Ms. Chotmanee | I55: CAM-3 : Further investigation is required to identify the specific machine conditions and mechanisms contributing to the variation. ACC/SMT - Temporary Action: Optimize moisture control during ACC/SMT to minimize the reversible LC shift. - Permanent Action: Identify and eliminate the root cause at ACC by improving dielectric uniformity and stability. | P55: 46252
B56: PSGB2 (B20E337) | C56: ESR Blister: Conveyer machine make bubble of GB2,B2 | D56: ESR was high deviation in some lot, PSGB2 was high sensivity. (1) From analysis found polymer had black spot at internal polymer that means inner is not cover well (2)Another is insulate of polymer was not get good insulatuin peak so LC high & get ESR high also. Blister : Conveyer had high temp & low hu at machine no Z1, EE BOL already fix it & GB2 case specify to not apply this machine (shape of anode were effect to blister). | G56: Ms. Supatsara Ms. Paemika Ms. Kanlaya | I56: First, conduct a detailed analysis to identify the process factors contributing to the ESR differences between the low ESR and high ESR groups, and determine the key parameters driving the variation We are currently investigating potential blister formation associated with abnormalities in the NR conveyor of the Z1 equipment. The objective is to clarify the blister formation mechanism, identify the root cause, and implement permanent corrective actions to prevent recurrence. | P56: 46248
B57: PSLB2 (B20E477) | C57: ESR High powder grade LC Weak at welding machine | D57: ESR level and variability increased after 250KCV implementation. However, the presence of both good and bad lots suggests that process variation remains, requiring further investigation to identify and eliminate the sources of inconsistency LC --> check LC tendency by M/C amd LC before/after welding | G57: Ms. Supatsara Ms. Paemika Ms. Kanlaya | I57: First, conduct a detailed analysis to identify the process factors contributing to the ESR differences between the low ESR and high ESR groups, and determine the key parameters driving the variation QOD to improve LC by change M-Aging volt from 2.5 to 5V (Today Aug 13'26 apply 3 lot of change review) -->This action will get benefit to ESR | P57: E/Aug'26
B58: PSLB2 (B20J107) (B21A476) (B20J227) | C58: App : Terminal Red | D58: From Analysis data -Gule mixing condition was not good (A&B) was not mix well -Consider another factor | G58: Ms. Supatsara Ms. Chantira Mr. Nonthawat | I58: -Finished experiment Mazerustar mixing machine, get good result for homogenous -Trial on 13 Aug,26 on 2HD(FA8) welding machine 3 lots, wait for result | P58: 46248
B59: PSLB15 | C59: Terminal red B150J227M | D59: Partial apply reduce glue quantity 25mg to 15mg (QOD plan within 21-Aug) | G59: TE (NPD) Mr. Suwicha Ms. Narakorn | I59: Defective was low ratio, TE under conclude the result | P59: 46255
A60: 46246 | B60: FPSA3 (A30J107) | C60: ESR Problem from L/F lot and Problems beyond L/F. Inprocess-DW CAM3 Dimension | D60: ESR : Remaining WIP for L/F problem = 6 Lots Problems beyond L/F. --> Focus to Mold clamp. CAM-3 defect occurrence appears to be related to both the dicing process and the Pick & Place (P&P) machine. A significant difference in defect levels has been observed among machines, with some showing normal performance while others exhibit considerably higher defect rates. | G60: Mr. Jirapat Mr. Pawekorn | I60: ESR '1. Feedback to supplier about L/F dimension. 2. Standardize L/F dimensional control to reduce ESR variation. | P60: 46248
B61: FPSA08 (A081C226) | C61: In-process-DW CAM3 Dimension CAM2 Mold-chip | D61: CAM-3 defect occurrence appears to be related to both the dicing process and the Pick & Place (P&P) machine. A significant difference in defect levels has been observed among machines, with some showing normal performance while others exhibit considerably higher defect rates. LC shift at ACC is a reversible heat and moisture effect, not permanent dielectric damage. The recovery after M-Treatment confirms that the change is temporary and moisture-related. SMT LC shift is a reversible thermal/moisture-related phenomenon rather than permanent degradation. | G61: Ms. Sasitorn Ms. Chotmanee | I61: CAM-3 : Further investigation is required to identify the specific machine conditions and mechanisms contributing to the variation. ACC/SMT - Temporary Action: Optimize moisture control during ACC/SMT to minimize the reversible LC shift. - Permanent Action: Identify and eliminate the root cause at ACC by improving dielectric uniformity and stability. | P61: 46252
B62: PSGB2 (B20E337) | C62: ESR Blister: Conveyer machine make bubble of GB2,B2 | D62: ESR was high deviation in some lot, PSGB2 was high sensivity. (1) From analysis found polymer had black spot at internal polymer that means inner is not cover well (2)Another is insulate of polymer was not get good insulatuin peak so LC high & get ESR high also. Blister : Conveyer had high temp & low hu at machine no Z1, EE BOL already fix it & GB2 case specify to not apply this machine (shape of anode were effect to blister). | G62: Ms. Supatsara Ms. Paemika Ms. Kanlaya | I62: First, conduct a detailed analysis to identify the process factors contributing to the ESR differences between the low ESR and high ESR groups, and determine the key parameters driving the variation We are currently investigating potential blister formation associated with abnormalities in the NR conveyor of the Z1 equipment. The objective is to clarify the blister formation mechanism, identify the root cause, and implement permanent corrective actions to prevent recurrence. | P62: 46248
B63: PSLB2 (B20E477) | C63: ESR High powder grade LC Weak at welding machine | D63: ESR level and variability increased after 250KCV implementation. However, the presence of both good and bad lots suggests that process variation remains, requiring further investigation to identify and eliminate the sources of inconsistency LC --> check LC tendency by M/C amd LC before/after welding | G63: Ms. Supatsara Ms. Paemika Ms. Kanlaya | I63: First, conduct a detailed analysis to identify the process factors contributing to the ESR differences between the low ESR and high ESR groups, and determine the key parameters driving the variation QOD to improve LC by change M-Aging volt from 2.5 to 5V (Today Aug 13'26 apply 3 lot of change review) -->This action will get benefit to ESR | P63: E/Aug'26
B64: PSLB2 (B20J107) (B21A107) (B21C336) | C64: App : Terminal Red | D64: From Analysis data -Gule mixing condition was not good (A&B) was not mix well -Consider another factor | G64: Ms. Supatsara Ms. Chantira Mr. Nonthawat | I64: -Finished experiment Mazerustar mixing machine, get good result for homogenous -Trial on 13 Aug,26 on 2HD(FA8) welding machine 3 lots, wait for result | P64: 46248
B65: PSLB15 | C65: Terminal red B150J227M | D65: Partial apply reduce glue quantity 25mg to 15mg (QOD plan within 21-Aug) | G65: TE (NPD) Suwicha Narakorn Team | I65: Defective was low ratio, TE under conclude the result | P65: 46255
A66: 46245 | B66: FPSA3 (A30J107) | C66: ESR Problem from L/F lot | D66: Remaining WIP for L/F problem | G66: Mr. Jirapat Mr. Pawekorn | I66: 1. Feedback to supplier about L/F dimension. 2. Work closely with QA to monitor L/F dimensional variation and its impact on ESR performance, and establish standardized control criteria. | P66: 46248
B67: FPSA2 (A21N396) | C67: App : Terminal Scratch CO : SH (Open) | D67: Root cause investigation is ongoing. (Terminal scratch --> 4M checking) | G67: Ms. Sasitorn Ms. Chotmanee Ms. Parichat Mr. Taksin | I67: 1. Clarify the defective with marginal sample with QA team and check the solderability test for verify functionality. 2. Conduct an on-site inspection to verify the defect mechanism and identify potential contributing factors. | P67: 46248
B68: PSGB2 (B20E337) | C68: ESR & Blister Blister: Conveyer machine make bubble of GB2,B2 | D68: ESR was high deviation in some lot, PSGB2 was high sensivity. (1) From analysis found polymer had black spot at internal polymer that means inner is not cover well (2)Another is insulate of polymer was not get good insulatuin peak so LC high & get ESR high also. Blister : Conveyer had high temp & low hu at machine no Z1, EE BOL already fix it & GB2 case specify to not apply this machine (shape of anode were effect to blister). | G68: Ms. Supatsara Ms. Paemika Ms. Kanlaya | I68: First, conduct a detailed analysis to identify the process factors contributing to the ESR differences between the low ESR and high ESR groups, and determine the key parameters driving the variation We are currently investigating potential blister formation associated with abnormalities in the NR conveyor of the Z1 equipment. The objective is to clarify the blister formation mechanism, identify the root cause, and implement permanent corrective actions to prevent recurrence. | P68: 46248
B69: PSLB2 (B20E477) | C69: ESR and LC | D69: ESR level and variability increased after 250KCV implementation. However, the presence of both good and bad lots suggests that process variation remains, requiring further investigation to identify and eliminate the sources of inconsistency LC --> check LC tendency by M/C amd LC before/after welding | G69: Ms. Supatsara Ms. Paemika Ms. Kanlaya | I69: First, conduct a detailed analysis to identify the process factors contributing to the ESR differences between the low ESR and high ESR groups, and determine the key parameters driving the variation | P69: E/Aug'26
B70: PSLB2 (B20J107) (B21A107) (B21C336) | C70: App : Terminal Red | D70: From Analysis data -Gule mixing condition was not good (A&B) was not mix well -Consider another factor | G70: Ms. Supatsara Ms. Chantira Mr. Nonthawat | I70: -Finished experiment Mazerustar mixing machine, get good result -Will trial on 13 Aug,26 on 2HD welding machine | P70: 46248
A71: 46244 | B71: FPSA3 (A30J107) | C71: ESR Problem from L/F lot | D71: Remaining WIP for L/F problem | G71: Mr. Jirapat Mr. Pawekorn | I71: 1. Feedback to supplier about L/F dimension. 2. Work closely with QA to monitor L/F dimensional variation and its impact on ESR performance, and establish standardized control criteria. | P71: 46248
B72: FPSA2 (A21N396) | C72: App : Terminal Scratch CO : SH (Open) | D72: Root cause investigation is ongoing. (Terminal scratch --> 4M checking) | G72: Ms. Sasitorn Ms. Chotmanee Ms. Parichat Mr. Taksin | I72: 1. Clarify the defective with marginal sample with QA team and check the solderability test for verify functionality. 2. Conduct an on-site inspection to verify the defect mechanism and identify potential contributing factors. | P72: 46248
B73: PSGB2 (B20E337) | C73: ESR & Blister Blister: Conveyer machine make bubble of GB2,B2 | D73: ESR was high deviation in some lot, PSGB2 was high sensivity. (1) From analysis found polymer had black spot at internal polymer that means inner is not cover well (2)Another is insulate of polymer was not get good insulatuin peak so LC high & get ESR high also. Blister : Conveyer had high temp & low hu at machine no Z1, EE BOL already fix it & GB2 case specify to not apply this machine (shape of anode were effect to blister). | G73: Ms. Supatsara Ms. Paemika Ms. Kanlaya | I73: First, conduct a detailed analysis to identify the process factors contributing to the ESR differences between the low ESR and high ESR groups, and determine the key parameters driving the variation We are currently investigating potential blister formation associated with abnormalities in the NR conveyor of the Z1 equipment. The objective is to clarify the blister formation mechanism, identify the root cause, and implement permanent corrective actions to prevent recurrence. | P73: 46248
...

Sheet Daily_Yield_SC
A1: =TODAY()-1 -> 46257
D3: Target | G3: 46235 | J3: 46236 | M3: 46237 | P3: 46238 | S3: 46239 | V3: 46240 | Y3: 46241 | AB3: 46242 | AE3: 46243 | AH3: 46244 | AK3: 46245 | AN3: 46246 | AQ3: 46247 | AT3: 46248 | AW3: 46249 | AZ3: 46250 | BC3: 46251 | BF3: 46252 | BI3: 46253 | BL3: 46254 | BO3: 46255 | BR3: 46256 | BU3: 46257 | BX3: 46258 | CA3: 46259 | CD3: 46260 | CG3: 46261 | CJ3: 46262 | CM3: 46263 | CP3: 46264 | CS3: 46265 | CV3: MTD
B4: Sub | C4: Case | D4: %Yield | E4: Output (KP) | F4: Lot | G4: %Yield | H4: Output (KP) | I4: Lot | J4: %Yield | K4: Output (KP) | L4: Lot | M4: %Yield | N4: Output (KP) | O4: Lot | P4: %Yield | Q4: Output (KP) | R4: Lot | S4: %Yield | T4: Output (KP) | U4: Lot | V4: %Yield | W4: Output (KP) | X4: Lot | Y4: %Yield | Z4: Output (KP) | AA4: Lot | AB4: %Yield | AC4: Output (KP) | AD4: Lot | AE4: %Yield | AF4: Output (KP) | AG4: Lot | AH4: %Yield | AI4: Output (KP) | AJ4: Lot | AK4: %Yield | AL4: Output (KP) | AM4: Lot | AN4: %Yield | AO4: Output (KP) | AP4: Lot | AQ4: %Yield | AR4: Output (KP) | AS4: Lot | AT4: %Yield | AU4: Output (KP) | AV4: Lot | AW4: %Yield | AX4: Output (KP) | AY4: Lot | AZ4: %Yield | BA4: Output (KP) | BB4: Lot | BC4: %Yield | BD4: Output (KP) | BE4: Lot | BF4: %Yield | BG4: Output (KP) | BH4: Lot | BI4: %Yield | BJ4: Output (KP) | BK4: Lot | BL4: %Yield | BM4: Output (KP) | BN4: Lot | BO4: %Yield | BP4: Output (KP) | BQ4: Lot | BR4: %Yield | BS4: Output (KP) | BT4: Lot | BU4: %Yield | BV4: Output (KP) | BW4: Lot | BX4: %Yield | BY4: Output (KP) | BZ4: Lot | CA4: %Yield | CB4: Output (KP) | CC4: Lot | CD4: %Yield | CE4: Output (KP) | CF4: Lot | CG4: %Yield | CH4: Output (KP) | CI4: Lot | CJ4: %Yield | CK4: Output (KP) | CL4: Lot | CM4: %Yield | CN4: Output (KP) | CO4: Lot | CP4: %Yield | CQ4: Output (KP) | CR4: Lot | CS4: %Yield | CT4: Output (KP) | CU4: Lot | CV4: %Yield | CW4: Output (KP) | CX4: Lot | CY4: Diff with Target
A5: SC | B5: Can | D5: 98.45 | E5: 750 | F5: 132 | G5: 95.8 | H5: =21367/1000 -> 21.367 | I5: 4 | J5: 99.44 | K5: =8853/1000 -> 8.853 | L5: 2 | M5: 98.18 | N5: =34982/1000 -> 34.982 | O5: 7 | P5: 98.73 | Q5: =31273/1000 -> 31.273 | R5: 7 | S5: 98.64 | T5: =27283/1000 -> 27.283 | U5: 3 | V5: 98.76 | W5: =63511/1000 -> 63.511 | X5: 9 | Y5: 98.59 | Z5: =11733/1000 -> 11.733 | AA5: 2 | AB5: 98.58 | AC5: =12655/1000 -> 12.655 | AD5: 1 | AE5: 98.93 | AF5: =11240/1000 -> 11.24 | AG5: 3 | AH5: 96.88 | AI5: =10361/1000 -> 10.361 | AJ5: 4 | AK5: 98.57 | AL5: =51765/1000 -> 51.765 | AM5: 9 | AO5: 0 | AP5: 0 | AQ5: 97.9 | AR5: =21849/1000 -> 21.849 | AS5: 5 | AT5: 98.56 | AU5: =17846/1000 -> 17.846 | AV5: 4 | AW5: 99.01 | AX5: =31658/1000 -> 31.658 | AY5: 4 | AZ5: 99 | BA5: =52966/1000 -> 52.966 | BB5: 7 | BC5: 98.17 | BD5: =43026/1000 -> 43.026 | BE5: 8 | BF5: 98.44 | BG5: =15774/1000 -> 15.774 | BH5: 4 | BI5: 93.67 | BJ5: 276 | BK5: 1 | BL5: 98.45 | BM5: =16341/1000 -> 16.341 | BN5: 3 | CV5: =AVERAGE(G5,J5,M5,P5,S5,V5,Y5,AB5,AE5,AH5,AK5,AN5,AQ5,AT5,AW5,AZ5,BC5,BF5,BI5,BL5,BO5,BR5,BU5,BX5,CA5,CD5,CG5,CJ5,CM5,CP5,CS5) -> 98.121053 | CW5: =SUM(H5,K5,N5,Q5,T5,W5,Z5,AC5,AF5,AI5,AL5,AO5,AR5,AU5,AX5,BA5,BD5,BG5,BJ5,BM5,BP5,BS5,BV5,BY5,CB5,CE5,CH5,CK5,CN5,CQ5,CT5) -> 760.483 | CX5: =SUM(I5,L5,O5,R5,U5,X5,AA5,AD5,AG5,AJ5,AM5,AP5,AS5,AV5,AY5,BB5,BE5,BH5,BK5,BN5,BQ5,BT5,BW5,BZ5,CC5,CF5,CI5,CL5,CO5,CR5,CU5) -> 87 | CY5: =CV5-D5 -> -0.32894737
A6: (End Prod) | B6: FC | D6: 99.1 | E6: 1600 | F6: 121 | G6: 99.42 | H6: =30000/1000 -> 30 | I6: 3 | J6: 99.36 | K6: =49000/1000 -> 49 | L6: 4 | M6: 99.01 | N6: =37500/1000 -> 37.5 | O6: 3 | P6: 99.3 | Q6: =74000/1000 -> 74 | R6: 6 | S6: 98.92 | T6: =36500/1000 -> 36.5 | U6: 3 | V6: 99.25 | W6: =77000/1000 -> 77 | X6: 6 | Y6: 99 | Z6: =54900/1000 -> 54.9 | AA6: 5 | AB6: 99.05 | AC6: =20500/1000 -> 20.5 | AD6: 2 | AE6: 98.99 | AF6: =36700/1000 -> 36.7 | AG6: 3 | AH6: 99.07 | AI6: =86200/1000 -> 86.2 | AJ6: 7 | AK6: 99.45 | AL6: =81500/1000 -> 81.5 | AM6: 5 | AO6: 0 | AP6: 0 | AQ6: 98.37 | AR6: =47700/1000 -> 47.7 | AS6: 4 | AT6: 99.55 | AU6: =40000/1000 -> 40 | AV6: 3 | AW6: 98.92 | AX6: =37500/1000 -> 37.5 | AY6: 3 | AZ6: 99.36 | BA6: =54500/1000 -> 54.5 | BB6: 5 | BC6: 99.53 | BD6: =33000/1000 -> 33 | BE6: 2 | BF6: 99.54 | BG6: =31500/1000 -> 31.5 | BH6: 2 | BI6: 99.35 | BJ6: =116500/1000 -> 116.5 | BK6: 10 | BL6: 99.46 | BM6: =50000/1000 -> 50 | BN6: 4 | CV6: =AVERAGE(G6,J6,M6,P6,S6,V6,Y6,AB6,AE6,AH6,AK6,AN6,AQ6,AT6,AW6,AZ6,BC6,BF6,BI6,BL6,BO6,BR6,BU6,BX6,CA6,CD6,CG6,CJ6,CM6,CP6,CS6) -> 99.205263 | CW6: =SUM(H6,K6,N6,Q6,T6,W6,Z6,AC6,AF6,AI6,AL6,AO6,AR6,AU6,AX6,BA6,BD6,BG6,BJ6,BM6,BP6,BS6,BV6,BY6,CB6,CE6,CH6,CK6,CN6,CQ6,CT6) -> 994.5 | CX6: =SUM(I6,L6,O6,R6,U6,X6,AA6,AD6,AG6,AJ6,AM6,AP6,AS6,AV6,AY6,BB6,BE6,BH6,BK6,BN6,BQ6,BT6,BW6,BZ6,CC6,CF6,CI6,CL6,CO6,CR6,CU6) -> 80 | CY6: =CV6-D6 -> 0.10526316
B7: FM | D7: 99.2 | E7: 1200 | F7: 91 | G7: 99.59 | H7: =59067/1000 -> 59.067 | I7: 4 | J7: 99.63 | K7: =17000/1000 -> 17 | L7: 1 | N7: 0 | O7: 0 | P7: 99.71 | Q7: =9000/1000 -> 9 | R7: 1 | S7: 99.54 | T7: =106879/1000 -> 106.879 | U7: 8 | V7: 99.46 | W7: =80198/1000 -> 80.198 | X7: 7 | Y7: 99.55 | Z7: =31729/1000 -> 31.729 | AA7: 2 | AB7: 99.7 | AC7: =9063/1000 -> 9.063 | AD7: 1 | AE7: 99.73 | AF7: =19000/1000 -> 19 | AG7: 1 | AH7: 99.5 | AI7: =35114/1000 -> 35.114 | AJ7: 3 | AK7: 99.57 | AL7: =38000/1000 -> 38 | AM7: 2 | AO7: 0 | AP7: 0 | AR7: 0 | AS7: 0 | AT7: 99.64 | AU7: =43000/1000 -> 43 | AV7: 3 | AW7: 99.54 | AX7: =98494/1000 -> 98.494 | AY7: 9 | AZ7: 99.53 | BA7: =59262/1000 -> 59.262 | BB7: 5 | BC7: 99.36 | BD7: =43296/1000 -> 43.296 | BE7: 4 | BF7: 99.59 | BG7: =50065/1000 -> 50.065 | BH7: 3 | BI7: 99.63 | BJ7: =38000/1000 -> 38 | BK7: 2 | BL7: 99.55 | BM7: =51907/1000 -> 51.907 | BN7: 4 | CV7: =AVERAGE(G7,J7,M7,P7,S7,V7,Y7,AB7,AE7,AH7,AK7,AN7,AQ7,AT7,AW7,AZ7,BC7,BF7,BI7,BL7,BO7,BR7,BU7,BX7,CA7,CD7,CG7,CJ7,CM7,CP7,CS7) -> 99.577647 | CW7: =SUM(H7,K7,N7,Q7,T7,W7,Z7,AC7,AF7,AI7,AL7,AO7,AR7,AU7,AX7,BA7,BD7,BG7,BJ7,BM7,BP7,BS7,BV7,BY7,CB7,CE7,CH7,CK7,CN7,CQ7,CT7) -> 789.074 | CX7: =SUM(I7,L7,O7,R7,U7,X7,AA7,AD7,AG7,AJ7,AM7,AP7,AS7,AV7,AY7,BB7,BE7,BH7,BK7,BN7,BQ7,BT7,BW7,BZ7,CC7,CF7,CI7,CL7,CO7,CR7,CU7) -> 60 | CY7: =CV7-D7 -> 0.37764706
B8: Grand Total | D8: 99 | E8: =SUM(E5:E7) -> 3550 | F8: =SUM(F5:F7) -> 344 | G8: =(G5*H5/H8)+(G6*H6/H8)+(G7*H7/H8) -> 98.810521 | H8: =SUM(H5:H7) -> 110.434 | I8: =SUM(I5:I7) -> 11 | J8: =(J5*K5/K8)+(J6*K6/K8)+(J7*K7/K8) -> 99.430782 | K8: =SUM(K5:K7) -> 74.853 | L8: =SUM(L5:L7) -> 7 | M8: =(M5*N5/N8)+(M6*N6/N8)+(M7*N7/N8) -> 98.609417 | N8: =SUM(N5:N7) -> 72.482 | O8: =SUM(O5:O7) -> 10 | P8: =(P5*Q5/Q8)+(P6*Q6/Q8)+(P7*Q7/Q8) -> 99.1763 | Q8: =SUM(Q5:Q7) -> 114.273 | R8: =SUM(R5:R7) -> 14 | S8: =(S5*T5/T8)+(S6*T6/T8)+(S7*T7/T8) -> 99.26352 | T8: =SUM(T5:T7) -> 170.662 | U8: =SUM(U5:U7) -> 14 | V8: =(V5*W5/W8)+(V6*W6/W8)+(V7*W7/W8) -> 99.185305 | W8: =SUM(W5:W7) -> 220.709 | X8: =SUM(X5:X7) -> 22 | Y8: =(Y5*Z5/Z8)+(Y6*Z6/Z8)+(Y7*Z7/Z8) -> 99.128509 | Z8: =SUM(Z5:Z7) -> 98.362 | AA8: =SUM(AA5:AA7) -> 9 | AB8: =(AB5*AC5/AC8)+(AB6*AC6/AC8)+(AB7*AC7/AC8) -> 99.048652 | AC8: =SUM(AC5:AC7) -> 42.218 | AD8: =SUM(AD5:AD7) -> 4 | AE8: =(AE5*AF5/AF8)+(AE6*AF6/AF8)+(AE7*AF7/AF8) -> 99.189964 | AF8: =SUM(AF5:AF7) -> 66.94 | AG8: =SUM(AG5:AG7) -> 7 | AH8: =(AH5*AI5/AI8)+(AH6*AI6/AI8)+(AH7*AI7/AI8) -> 99.012346 | AI8: =SUM(AI5:AI7) -> 131.675 | AJ8: =SUM(AJ5:AJ7) -> 14 | AK8: =(AK5*AL5/AL8)+(AK6*AL6/AL8)+(AK7*AL7/AL8) -> 99.210645 | AL8: =SUM(AL5:AL7) -> 171.265 | AM8: =SUM(AM5:AM7) -> 16 | AN8: =(AN5*AO5/AO8)+(AN6*AO6/AO8)+(AN7*AO7/AO8) -> #DIV/0! | AO8: =SUM(AO5:AO7) -> 0 | AP8: =SUM(AP5:AP7) -> 0 | AQ8: =(AQ5*AR5/AR8)+(AQ6*AR6/AR8)+(AQ7*AR7/AR8) -> 37.723461 | AR8: 181.088 | AS8: 21 | AT8: =(AT5*AU5/AU8)+(AT6*AU6/AU8)+(AT7*AU7/AU8) -> 99.413182 | AU8: =SUM(AU5:AU7) -> 100.846 | AV8: =SUM(AV5:AV7) -> 10 | AW8: =(AW5*AX5/AX8)+(AW6*AX6/AX8)+(AW7*AX7/AX8) -> 99.301239 | AX8: =SUM(AX5:AX7) -> 167.652 | AY8: =SUM(AY5:AY7) -> 16 | AZ8: =(AZ5*BA5/BA8)+(AZ6*BA6/BA8)+(AZ7*BA7/BA8) -> 99.306061 | BA8: =SUM(BA5:BA7) -> 166.728 | BB8: =SUM(BB5:BB7) -> 17 | BC8: =(BC5*BD5/BD8)+(BC6*BD6/BD8)+(BC7*BD7/BD8) -> 98.977917 | BD8: =SUM(BD5:BD7) -> 119.322 | BE8: =SUM(BE5:BE7) -> 14 | BF8: =(BF5*BG5/BG8)+(BF6*BG6/BG8)+(BF7*BG7/BG8) -> 99.387459 | BG8: =SUM(BG5:BG7) -> 97.339 | BH8: =SUM(BH5:BH7) -> 9 | BI8: =(BI5*BJ5/BJ8)+(BI6*BJ6/BJ8)+(BI7*BJ7/BJ8) -> 95.733182 | BJ8: =SUM(BJ5:BJ7) -> 430.5 | BK8: =SUM(BK5:BK7) -> 13 | BL8: =(BL5*BM5/BM8)+(BL6*BM6/BM8)+(BL7*BM7/BM8) -> 99.359933 | BM8: =SUM(BM5:BM7) -> 118.248 | BN8: =SUM(BN5:BN7) -> 11 | BO8: =(BO5*BP5/BP8)+(BO6*BP6/BP8)+(BO7*BP7/BP8) -> #DIV/0! | BP8: =SUM(BP5:BP7) -> 0 | BQ8: =SUM(BQ5:BQ7) -> 0 | BR8: =(BR5*BS5/BS8)+(BR6*BS6/BS8)+(BR7*BS7/BS8) -> #DIV/0! | BS8: =SUM(BS5:BS7) -> 0 | BT8: =SUM(BT5:BT7) -> 0 | BU8: =(BU5*BV5/BV8)+(BU6*BV6/BV8)+(BU7*BV7/BV8) -> #DIV/0! | BV8: =SUM(BV5:BV7) -> 0 | BW8: =SUM(BW5:BW7) -> 0 | CV8: =(CV5*CW5/CW8)+(CV6*CW6/CW8)+(CV7*CW7/CW8) -> 98.996665 | CW8: =SUM(CW5:CW7) -> 2544.057 | CX8: =SUM(CX5:CX7) -> 227 | CY8: =CV8-D8 -> -0.0033348489
A11: Date | B11: Series | C11: Problem | D11: Action | E11: PIC | F11: Progress
A12: 46253 | B12: CAN | C12: 1)LC-SD defective from M/C (Big size product ->Less lot size-higher impact) | D12: Improve panel damage | E12: EE Mtnc. | F12: On going
A13: 46252 | B13: CAN | C13: 1)LC-SD defective from M/C (Big size product ->Less lot size-higher impact) | D13: Improve panel damage | E13: EE Mtnc. | F13: On going
A14: 46251 | B14: CAN | C14: 1)LC-SD defective from M/C (Big size product ->Less lot size-higher impact) | D14: Improve panel damage | E14: EE Mtnc. | F14: On going
A15: 46249 | B15: FC | C15: Hi-LC def 1 lot, suspect swaging incomplete. | D15: Recheck swaging cond. | E15: PE | F15: On going
A16: 46248 | B16: CAN | C16: SD def over from 1) Re-screen liq leak 2) Element scratch from 17MUF. | D16: 1) Feedback & Improve at Element process. 2) Review element/insulator design. | E16: PE | F16: On going
B17: FC | C17: 1) Outer case scratch/ terminal bending 2) C def from operating in CC line. | D17: Keep check & control process effect from M/C | E17: Mtnc. | F17: On going
A18: 46244 | B18: FC | C18: SD Def from tighten SD spec for expired element | D18: Review SD spec | E18: PE | F18: On going
C19: SD def suspect over reject from operating at CC line. | D19: Keep maintain probe and panel. | E19: EE Mtnc. | F19: On going
C20: SD defective -> Re-screen liq-leak many round. | D20: Keep check & control process | E20: PE | F20: On going
C21: Laser Marking fade from change product size at plate inserting FC2 (8.4 mm to 8.1 mm). | D21: Issue adjusting instruction for product model change | E21: EE Mtnc. | F21: Not started
B22: CAN | C22: C def from over reject(defective was re-screened but unable to fix MES data) | D22: Confirm C meas. Cond. | E22: PE | F22: On going
A23: 46243 | B23: FC | C23: SD def suspect over reject from operating at CC line. | D23: Keep maintain probe and panel. | E23: EE Mtnc. | F23: On going
A24: 46242 | B24: FC | C24: 1) C def from low paste weight / Hi-C def from probe error. 2) LC def from over reject. | D24: 1) Check & Change probe 2) Improve paste printing op. | E24: PE | F24: On going
A25: 46240 | B25: FC | C25: Plate crack & terminal bending NG from plate inserting MC | D25: Adjust M/C for suitable cond. | E25: EE Mtnc. | F25: On going
A26: 46239 | B26: FC | C26: SD Def from tighten SD spec for expired element | D26: Review SD spec | E26: PE | F26: On going
A27: 46237 | B27: CAN | C27: 1)Outer case scratch from M/C | D27: Add sensor at inloader | E27: EE Eng. | F27: Not started
C28: 2)LC-SD defective from M/C | D28: Improve panel damage | E28: EE Mtnc. | F28: On going
A29: 46235 | B29: CAN | C29: C def from NG Probe | D29: Check probe & re-screen def(Unable to fix def in MES) | E29: PE/EE | F29: Done
D44: Target | G44: 46204 | J44: 46205 | M44: 46206 | P44: 46207 | S44: 46208 | V44: 46209 | Y44: 46210 | AB44: 46211 | AE44: 46212 | AH44: 46213 | AK44: 46214 | AN44: 46215 | AQ44: 46216 | AT44: 46217 | AW44: 46218 | AZ44: 46219 | BC44: 46220 | BF44: 46221 | BI44: 46222 | BL44: 46223 | BO44: 46224 | BR44: 46225 | BU44: 46226 | BX44: 46227 | CA44: 46228 | CD44: 46229 | CG44: 46230 | CJ44: 46231 | CM44: 46232 | CP44: 46233 | CS44: 46234 | CV44: MTD
B45: Sub | C45: Case | D45: %Yield | E45: Output (KP) | F45: Lot | G45: %Yield | H45: Output (KP) | I45: Lot | J45: %Yield | K45: Output (KP) | L45: Lot | M45: %Yield | N45: Output (KP) | O45: Lot | P45: %Yield | Q45: Output (KP) | R45: Lot | S45: %Yield | T45: Output (KP) | U45: Lot | V45: %Yield | W45: Output (KP) | X45: Lot | Y45: %Yield | Z45: Output (KP) | AA45: Lot | AB45: %Yield | AC45: Output (KP) | AD45: Lot | AE45: %Yield | AF45: Output (KP) | AG45: Lot | AH45: %Yield | AI45: Output (KP) | AJ45: Lot | AK45: %Yield | AL45: Output (KP) | AM45: Lot | AN45: %Yield | AO45: Output (KP) | AP45: Lot | AQ45: %Yield | AR45: Output (KP) | AS45: Lot | AT45: %Yield | AU45: Output (KP) | AV45: Lot | AW45: %Yield | AX45: Output (KP) | AY45: Lot | AZ45: %Yield | BA45: Output (KP) | BB45: Lot | BC45: %Yield | BD45: Output (KP) | BE45: Lot | BF45: %Yield | BG45: Output (KP) | BH45: Lot | BI45: %Yield | BJ45: Output (KP) | BK45: Lot | BL45: %Yield | BM45: Output (KP) | BN45: Lot | BO45: %Yield | BP45: Output (KP) | BQ45: Lot | BR45: %Yield | BS45: Output (KP) | BT45: Lot | BU45: %Yield | BV45: Output (KP) | BW45: Lot | BX45: %Yield | BY45: Output (KP) | BZ45: Lot | CA45: %Yield | CB45: Output (KP) | CC45: Lot | CD45: %Yield | CE45: Output (KP) | CF45: Lot | CG45: %Yield | CH45: Output (KP) | CI45: Lot | CJ45: %Yield | CK45: Output (KP) | CL45: Lot | CM45: %Yield | CN45: Output (KP) | CO45: Lot | CP45: %Yield | CQ45: Output (KP) | CR45: Lot | CS45: %Yield | CT45: Output (KP) | CU45: Lot | CV45: %Yield | CW45: Output (KP) | CX45: Lot | CY45: Diff with Target
A46: SC | B46: Can | D46: 98.45 | E46: 800 | F46: 148 | G46: 98.53 | H46: 39.619 | I46: 5 | J46: 98.32 | K46: 15.705 | L46: 4 | M46: 98.53 | N46: 18.073 | O46: 2 | P46: 98.55 | Q46: 17.508 | R46: 2 | S46: 99.11 | T46: 17.691 | U46: 3 | V46: 98.06 | W46: 5.958 | X46: 3 | Y46: 98.59 | Z46: 21.763 | AA46: 3 | AB46: 98.37 | AC46: 40.259 | AD46: 6 | AE46: 98.51 | AF46: 31.374 | AG46: 6 | AH46: 98.71 | AI46: 22.53 | AJ46: 3 | AK46: 98.56 | AL46: 83.5 | AM46: 2 | AN46: 98.91 | AO46: 13.846 | AP46: 3 | AQ46: 98.53 | AR46: 53.024 | AS46: 10 | AT46: 99.12 | AU46: =2026/1000 -> 2.026 | AV46: 1 | AW46: 98.01 | AX46: =37114/1000 -> 37.114 | AY46: 10 | AZ46: 97.54 | BA46: =34804/1000 -> 34.804 | BB46: 8 | BC46: 98.73 | BD46: =36398/1000 -> 36.398 | BE46: 7 | BF46: 99.18 | BG46: =21635/1000 -> 21.635 | BH46: 5 | BI46: 98.74 | BJ46: =27770/1000 -> 27.77 | BK46: 5 | BL46: 98.03 | BM46: =24441/1000 -> 24.441 | BN46: 9 | BO46: 97.22 | BP46: =46388/1000 -> 46.388 | BQ46: 8 | BR46: 96.68 | BS46: =78030/1000 -> 78.03 | BT46: 12 | BU46: 98.43 | BV46: =50782/1000 -> 50.782 | BW46: 8 | BX46: 98.95 | BY46: =23929/1000 -> 23.929 | BZ46: 6 | CA46: 98.93 | CB46: =39320/1000 -> 39.32 | CC46: 5 | CD46: 98.99 | CE46: =38110/1000 -> 38.11 | CF46: 4 | CG46: 98.91 | CH46: =25241/1000 -> 25.241 | CI46: 4 | CJ46: 98.65 | CK46: =32513/1000 -> 32.513 | CL46: 4 | CM46: 98.26 | CN46: =47228/1000 -> 47.228 | CO46: 6 | CV46: =AVERAGE(G46,J46,M46,P46,S46,V46,Y46,AB46,AE46,AH46,AK46,AN46,AQ46,AT46,AW46,AZ46,BC46,BF46,BI46,BL46,BO46,BR46,BU46,BX46,CA46,CD46,CG46,CJ46,CM46,CP46,CS46) -> 98.47069 | CW46: =SUM(H46,K46,N46,Q46,T46,W46,Z46,AC46,AF46,AI46,AL46,AO46,AR46,AU46,AX46,BA46,BD46,BG46,BJ46,BM46,BP46,BS46,BV46,BY46,CB46,CE46,CH46,CK46,CN46,CQ46,CT46) -> 946.579 | CX46: =SUM(I46,L46,O46,R46,U46,X46,AA46,AD46,AG46,AJ46,AM46,AP46,AS46,AV46,AY46,BB46,BE46,BH46,BK46,BN46,BQ46,BT46,BW46,BZ46,CC46,CF46,CI46,CL46,CO46,CR46,CU46) -> 154 | CY46: =CV46-D46 -> 0.020689655
A47: (End Prod) | B47: FC | D47: 99.1 | E47: 1550.0003 | F47: 117 | G47: 99.41 | H47: 38 | I47: 3 | J47: 99.61 | K47: 31.5 | L47: 2 | M47: 99.45 | N47: 37.5 | O47: 3 | P47: 99.28 | Q47: 55.5 | R47: 4 | S47: 99.42 | T47: 51 | U47: 4 | V47: 99.19 | W47: 38 | X47: 3 | Y47: 99.3 | Z47: 73 | AA47: 6 | AB47: 99.28 | AC47: 75 | AD47: 6 | AE47: 99.37 | AF47: 44.5 | AG47: 3 | AH47: 99.57 | AI47: 76.5 | AJ47: 5 | AK47: 99.24 | AL47: 48.95 | AM47: 4 | AN47: 99.02 | AO47: 63.4 | AP47: 5 | AQ47: 98.69 | AR47: 72.6 | AS47: 5 | AT47: 99.46 | AU47: =30500/1000 -> 30.5 | AV47: 2 | AW47: 99.45 | AX47: =44000/1000 -> 44 | AY47: 3 | AZ47: 99.09 | BA47: =50300/1000 -> 50.3 | BB47: 4 | BC47: 99.71 | BD47: =38000/1000 -> 38 | BE47: 2 | BF47: 99.3 | BG47: =19000/1000 -> 19 | BH47: 1 | BI47: 99.73 | BJ47: =37000/1000 -> 37 | BK47: 2 | BL47: 99.32 | BM47: =13000/1000 -> 13 | BN47: 1 | BO47: 99.6 | BP47: =31000/1000 -> 31 | BQ47: 2 | BR47: 99.68 | BS47: =19000/1000 -> 19 | BT47: 2 | BU47: 99.62 | BV47: =33000/1000 -> 33 | BW47: 2 | BX47: 99.43 | BY47: =51000/1000 -> 51 | BZ47: 5 | CA47: 99.36 | CB47: =45000/1000 -> 45 | CC47: 3 | CD47: 99.42 | CE47: =63500/1000 -> 63.5 | CF47: 5 | CG47: 98.77 | CH47: =30000/1000 -> 30 | CI47: 3 | CJ47: 99.5 | CK47: =37500/1000 -> 37.5 | CL47: 3 | CM47: 96.32 | CN47: =93000/1000 -> 93 | CO47: 8 | CV47: =AVERAGE(G47,J47,M47,P47,S47,V47,Y47,AB47,AE47,AH47,AK47,AN47,AQ47,AT47,AW47,AZ47,BC47,BF47,BI47,BL47,BO47,BR47,BU47,BX47,CA47,CD47,CG47,CJ47,CM47,CP47,CS47) -> 99.261724 | CW47: =SUM(H47,K47,N47,Q47,T47,W47,Z47,AC47,AF47,AI47,AL47,AO47,AR47,AU47,AX47,BA47,BD47,BG47,BJ47,BM47,BP47,BS47,BV47,BY47,CB47,CE47,CH47,CK47,CN47,CQ47,CT47) -> 1340.25 | CX47: =SUM(I47,L47,O47,R47,U47,X47,AA47,AD47,AG47,AJ47,AM47,AP47,AS47,AV47,AY47,BB47,BE47,BH47,BK47,BN47,BQ47,BT47,BW47,BZ47,CC47,CF47,CI47,CL47,CO47,CR47,CU47) -> 101 | CY47: =CV47-D47 -> 0.16172414
B48: FM | D48: 99.2 | E48: 1200 | F48: 94 | G48: 99.53 | H48: 17 | I48: 1 | J48: 99.51 | K48: 22 | L48: 2 | M48: 98.78 | N48: 18.927 | O48: 2 | P48: 99.7 | Q48: 33 | R48: 2 | S48: 99.62 | T48: 63.134 | U48: 4 | V48: 99.51 | W48: 46 | X48: 3 | Y48: 99.63 | Z48: 68.99 | AA48: 6 | AB48: 99.56 | AC48: 66.356 | AD48: 5 | AE48: 99.56 | AF48: 50.151 | AG48: 5 | AH48: 99.58 | AI48: 65.2 | AJ48: 5 | AK48: 99.49 | AL48: 38 | AM48: 3 | AN48: 99.39 | AO48: 80.744 | AP48: 6 | AQ48: 99.35 | AR48: 55.464 | AS48: 6 | AT48: 99.38 | AU48: =24665/1000 -> 24.665 | AV48: 2 | AW48: 99.26 | AX48: =38000/1000 -> 38 | AY48: 3 | AZ48: 99.68 | BA48: =12644/1000 -> 12.644 | BB48: 1 | BD48: 0 | BE48: 0 | BG48: 0 | BH48: 0 | BI48: 99.63 | BJ48: =37000/1000 -> 37 | BK48: 2 | BL48: 99.45 | BM48: =23800/1000 -> 23.8 | BN48: 2 | BO48: 99.65 | BP48: =37000/1000 -> 37 | BQ48: 2 | BR48: 99.72 | BS48: =25000/1000 -> 25 | BT48: 1 | BU48: 99.71 | BV48: =57000/1000 -> 57 | BW48: 4 | BX48: 99.65 | BY48: =86399/1000 -> 86.399 | BZ48: 7 | CA48: 99.64 | CB48: =49389/1000 -> 49.389 | CC48: 5 | CD48: 99.48 | CE48: =13000/1000 -> 13 | CF48: 1 | CG48: 99.8 | CH48: =38000/1000 -> 38 | CI48: 2 | CK48: 0 | CL48: 0 | CM48: 99.65 | CN48: =17090/1000 -> 17.09 | CO48: 1 | CV48: =AVERAGE(G48,J48,M48,P48,S48,V48,Y48,AB48,AE48,AH48,AK48,AN48,AQ48,AT48,AW48,AZ48,BC48,BF48,BI48,BL48,BO48,BR48,BU48,BX48,CA48,CD48,CG48,CJ48,CM48,CP48,CS48) -> 99.535 | CW48: =SUM(H48,K48,N48,Q48,T48,W48,Z48,AC48,AF48,AI48,AL48,AO48,AR48,AU48,AX48,BA48,BD48,BG48,BJ48,BM48,BP48,BS48,BV48,BY48,CB48,CE48,CH48,CK48,CN48,CQ48,CT48) -> 1083.953 | CX48: =SUM(I48,L48,O48,R48,U48,X48,AA48,AD48,AG48,AJ48,AM48,AP48,AS48,AV48,AY48,BB48,BE48,BH48,BK48,BN48,BQ48,BT48,BW48,BZ48,CC48,CF48,CI48,CL48,CO48,CR48,CU48) -> 83 | CY48: =CV48-D48 -> 0.335
B49: Grand Total | D49: 99 | E49: =SUM(E46:E48) -> 3550.0003 | F49: =SUM(F46:F48) -> 359 | G49: =(G46*H46/H49)+(G47*H47/H49)+(G48*H48/H49) -> 99.063085 | H49: =SUM(H46:H48) -> 94.619 | I49: =SUM(I46:I48) -> 9 | J49: =(J46*K46/K49)+(J47*K47/K49)+(J48*K48/K49) -> 99.285465 | K49: =SUM(K46:K48) -> 69.205 | L49: =SUM(L46:L48) -> 8 | M49: =(M46*N46/N49)+(M47*N47/N49)+(M48*N48/N49) -> 99.056601 | N49: =SUM(N46:N48) -> 74.5 | O49: =SUM(O46:O48) -> 7 | P49: =(P46*Q46/Q49)+(P47*Q47/Q49)+(P48*Q48/Q49) -> 99.29018 | Q49: =SUM(Q46:Q48) -> 106.008 | R49: =SUM(R46:R48) -> 8 | S49: =(S46*T46/T49)+(S47*T47/T49)+(S48*T48/T49) -> 99.474182 | T49: =SUM(T46:T48) -> 131.825 | U49: =SUM(U46:U48) -> 11 | V49: =(V46*W46/W49)+(V47*W47/W49)+(V48*W48/W49) -> 99.278791 | W49: =SUM(W46:W48) -> 89.958 | X49: =SUM(X46:X48) -> 9 | Y49: =(Y46*Z46/Z49)+(Y47*Z47/Z49)+(Y48*Z48/Z49) -> 99.344671 | Z49: =SUM(Z46:Z48) -> 163.753 | AA49: =SUM(AA46:AA48) -> 15 | AB49: =(AB46*AC46/AC49)+(AB47*AC47/AC49)+(AB48*AC48/AC49) -> 99.180581 | AC49: =SUM(AC46:AC48) -> 181.615 | AD49: =SUM(AD46:AD48) -> 17 | AE49: =(AE46*AF46/AF49)+(AE47*AF47/AF49)+(AE48*AF48/AF49) -> 99.231512 | AF49: =SUM(AF46:AF48) -> 126.025 | AG49: =SUM(AG46:AG48) -> 14 | AH49: =(AH46*AI46/AI49)+(AH47*AI47/AI49)+(AH48*AI48/AI49) -> 99.45599 | AI49: =SUM(AI46:AI48) -> 164.23 | AJ49: =SUM(AJ46:AJ48) -> 13 | AK49: =(AK46*AL46/AL49)+(AK47*AL47/AL49)+(AK48*AL48/AL49) -> 98.962617 | AL49: =SUM(AL46:AL48) -> 170.45 | AM49: =SUM(AM46:AM48) -> 9 | AN49: =(AN46*AO46/AO49)+(AN47*AO47/AO49)+(AN48*AO48/AO49) -> 99.199456 | AO49: =SUM(AO46:AO48) -> 157.99 | AP49: =SUM(AP46:AP48) -> 14 | AQ49: =(AQ46*AR46/AR49)+(AQ47*AR47/AR49)+(AQ48*AR48/AR49) -> 98.845297 | AR49: 181.088 | AS49: 21 | AT49: =(AT46*AU46/AU49)+(AT47*AU47/AU49)+(AT48*AU48/AU49) -> 99.413454 | AU49: =SUM(AU46:AU48) -> 57.191 | AV49: =SUM(AV46:AV48) -> 5 | AW49: =(AW46*AX46/AX49)+(AW47*AX47/AX49)+(AW48*AX48/AX49) -> 98.940705 | AX49: =SUM(AX46:AX48) -> 119.114 | AY49: =SUM(AY46:AY48) -> 16 | AZ49: =(AZ46*BA46/BA49)+(AZ47*BA47/BA49)+(AZ48*BA48/BA49) -> 98.614428 | BA49: =SUM(BA46:BA48) -> 97.748 | BB49: =SUM(BB46:BB48) -> 13 | BC49: =(BC46*BD46/BD49)+(BC47*BD47/BD49)+(BC48*BD48/BD49) -> 99.230551 | BD49: =SUM(BD46:BD48) -> 74.398 | BE49: =SUM(BE46:BE48) -> 9 | BF49: =(BF46*BG46/BG49)+(BF47*BG47/BG49)+(BF48*BG48/BG49) -> 99.236109 | BG49: =SUM(BG46:BG48) -> 40.635 | BH49: =SUM(BH46:BH48) -> 6 | BI49: =(BI46*BJ46/BJ49)+(BI47*BJ47/BJ49)+(BI48*BJ48/BJ49) -> 99.423502 | BJ49: =SUM(BJ46:BJ48) -> 101.77 | BK49: =SUM(BK46:BK48) -> 9 | BL49: =(BL46*BM46/BM49)+(BL47*BM47/BM49)+(BL48*BM48/BM49) -> 98.855689 | BM49: =SUM(BM46:BM48) -> 61.241 | BN49: =SUM(BN46:BN48) -> 12 | BO49: =(BO46*BP46/BP49)+(BO47*BP47/BP49)+(BO48*BP48/BP49) -> 98.651007 | BP49: =SUM(BP46:BP48) -> 114.388 | BQ49: =SUM(BQ46:BQ48) -> 12 | BR49: =(BR46*BS46/BS49)+(BR47*BS47/BS49)+(BR48*BS48/BS49) -> 97.769896 | BS49: =SUM(BS46:BS48) -> 122.03 | BT49: =SUM(BT46:BT48) -> 15 | BU49: =(BU46*BV46/BV49)+(BU47*BV47/BV49)+(BU48*BV48/BV49) -> 99.22719 | BV49: =SUM(BV46:BV48) -> 140.782 | BW49: =SUM(BW46:BW48) -> 14 | CV49: =(CV46*CW46/CW49)+(CV47*CW47/CW49)+(CV48*CW48/CW49) -> 99.127465 | CW49: =SUM(CW46:CW48) -> 3370.782 | CX49: =SUM(CX46:CX48) -> 338 | CY49: =CV49-D49 -> 0.12746495
A55: Date | B55: Series | C55: Problem | D55: Action | E55: PIC | F55: Progress
A56: 46218 | B56: CAN | C56: 1)LC-SD defective from M/C (Big size product ->Less lot size-higher impact) | D56: Improve panel damage | E56: EE Mtnc. | F56: On going
C57: 2)Outer case scratch from M/C | D57: Add sensor at inloader | E57: EE Eng. | F57: Not started
A58: 46219 | B58: CAN | C58: 1)LC-SD defective from M/C (Big size product ->Less lot size-higher impact) | D58: Improve panel damage | E58: EE Mtnc. | F58: On going
B59: FC | C59: LC-SD defective ->Big size operate in CAN line | D59: Improve panel damage | E59: EE Mtnc. | F59: On going
A60: 46223 | B60: CAN | C60: 1)LC-SD defective from M/C (Big size product ->Less lot size-higher impact) | D60: Improve panel damage | E60: EE Mtnc. | F60: On going
A61: 46224 | B61: CAN | C61: LC-SD defective -> Re-screen liq-leak many round for expired element which is MFG in problem period previous year. | D61: Keep check & control process | E61: PE | F61: On going
A62: 46225 | B62: CAN | C62: C defective 17MUF -> Low paste printing (Element stock before action) | D62: Add check item & trouble shooting for printing & combine operation. | E62: PE | F62: Done
...

Sheet Monthly_Yield_Ta-SC
D2: CY2025 | P2: CY2026
B3: Sub | C3: Case | D3: Jan'25 | E3: Feb | F3: Mar | G3: Apr | H3: May | I3: Jun | J3: Jul | K3: Aug | L3: Sep | M3: Oct | N3: Nov | O3: Dec | P3: Jan'26 | Q3: Feb | R3: Mar | S3: Apr | T3: May | U3: Jun | V3: Jul | W3: Aug | X3: Sep | Y3: Oct | Z3: Nov | AA3: Dec
A4: TaPoly | B4: FPS | C4: A3 | D4: 0.9147 | E4: 0.902 | F4: 0.9119 | G4: 0.9092 | H4: 0.9157 | I4: 0.9152 | J4: 0.9033 | K4: 0.8987 | L4: 0.8979 | M4: 0.8941 | N4: 0.891 | O4: 0.8725 | P4: 0.8631 | Q4: 0.8582 | R4: 0.8607 | S4: 0.8838 | T4: 0.9068 | U4: 0.901 | V4: 0.8924
A5: (E/I) | B5: FPS | C5: A2 | D5: 0.9338 | E5: 0.9422 | F5: 0.9388 | G5: 0.9307 | H5: 0.9168 | I5: 0.9307 | J5: 0.9393 | K5: 0.9448 | L5: 0.9508 | M5: 0.9456 | N5: 0.9493 | O5: 0.9476 | P5: 0.9363 | Q5: 0.9339 | R5: 0.9256 | S5: 0.9346 | T5: 0.9376 | U5: 0.9041 | V5: 0.9331
B6: FPS | C6: B3 | D6: 0.8877 | E6: 0.9425 | F6: 0.9264 | G6: 0.8589 | H6: 0.9034 | I6: 0.9028 | J6: 0.9164 | K6: 0.8691 | L6: 0.8705 | M6: 0.9352 | N6: 0.9308 | O6: 0.9293 | P6: 0.9285 | Q6: 0.9256 | R6: 0.9237 | S6: 0.9435 | T6: 0.9271 | U6: 0.9248 | V6: 0.9071
B7: FPS | C7: B10 | D7: 0.9257 | E7: 0.9304 | F7: 0.9273 | G7: 0.9297 | H7: 0.9161 | I7: 0.9167 | J7: 0.8824 | K7: 0.925 | L7: 0.8974 | M7: - | N7: - | O7: 0.8409 | P7: 0.9015 | Q7: 0.916 | R7: 0.9093 | S7: 0.9309 | T7: 0.9329 | U7: 0.9224
B8: FPS | C8: A08 | D8: 0.855 | E8: 0.822 | F8: 0.8582 | G8: 0.8634 | H8: 0.8127 | I8: 0.7869 | J8: 0.7675 | K8: 0.7377 | L8: 0.7293 | M8: 0.7469 | N8: 0.732 | O8: 0.8229 | P8: 0.8529 | Q8: 0.8752 | R8: 0.8456 | S8: 0.7945 | T8: 0.8572 | U8: 0.87 | V8: 0.848
B9: FPU | C9: A2 | V9: 0.7178
B10: FACE DOWN | C10: Total | D10: 0.9125 | E10: 0.9235 | F10: 0.9284 | G10: 0.9121 | H10: 0.904 | I10: 0.9097 | J10: 0.902 | K10: 0.8609 | L10: 0.8787 | M10: 0.8999 | N10: 0.8799 | O10: 0.896 | P10: 0.9051 | Q10: 0.9143 | R10: 0.8982 | S10: 0.9037 | T10: 0.9044 | U10: 0.901 | V10: 0.8835
B11: GPS | C11: P2 | D11: 0.8103 | E11: 0.835 | F11: 0.8567 | G11: 0.8312 | H11: 0.8408 | I11: 0.8099 | J11: 0.8024 | K11: 0.8479 | L11: 0.8314 | M11: 0.8494 | N11: 0.8338 | O11: 0.8684 | P11: 0.8173 | Q11: 0.7924 | R11: 0.8096 | S11: 0.8445 | T11: 0.8361 | U11: 0.8341 | V11: 0.8195
B12: GPS | C12: A3
B13: GPS | C13: Total | D13: 0.8103 | E13: 0.835 | F13: 0.8567 | G13: 0.8312 | H13: 0.8408 | I13: 0.8099 | J13: 0.8024 | K13: 0.8479 | L13: 0.8314 | M13: 0.8494 | N13: 0.8338 | O13: 0.8684 | P13: 0.8173 | Q13: 0.7924 | R13: 0.8096 | S13: 0.8445 | T13: 0.8361 | U13: 0.8341 | V13: 0.8195
B14: PSL | C14: A | D14: 0.9396 | E14: 0.9353 | F14: 0.9336 | G14: 0.92 | H14: 0.9287 | I14: 0.9284 | J14: 0.9129 | K14: 0.9218 | L14: 0.9209 | M14: 0.9331 | N14: 0.9363 | O14: 0.9378 | P14: 0.9425 | Q14: 0.9501 | R14: 0.9558 | S14: 0.9488 | T14: 0.948 | U14: 0.9446 | V14: 0.926
B15: PSL | C15: B3 | D15: 0.9337 | E15: 0.9322 | F15: 0.943 | G15: 0.9456 | H15: 0.9492 | I15: 0.9431 | J15: 0.9415 | K15: 0.9404 | L15: 0.9343 | M15: 0.9319 | N15: 0.9221 | O15: 0.9206 | P15: 0.9256 | Q15: 0.9258 | R15: 0.9224 | S15: 0.9327 | T15: 0.9347 | U15: 0.9282 | V15: 0.9248
B16: PSL | C16: B15 | D16: 0.9086 | E16: 0.937 | F16: 0.9433 | G16: 0.9335 | H16: 0.7734 | I16: - | J16: 0.8759 | K16: 0.9232 | L16: 0.8821 | M16: 0.9303 | N16: 0.9434 | O16: 0.8949 | P16: 0.7986 | Q16: 0.8689 | R16: 0.897 | S16: 0.8823 | T16: 0.819 | U16: 0.8329 | V16: 0.7903
B17: PSL | C17: B2 | D17: 0.9559 | E17: 0.9532 | F17: 0.9552 | G17: 0.9465 | H17: 0.9511 | I17: 0.9411 | J17: 0.928 | K17: 0.9286 | L17: 0.9281 | M17: 0.9337 | N17: 0.9393 | O17: 0.9075 | P17: 0.9174 | Q17: 0.9429 | R17: 0.917 | S17: 0.9309 | T17: 0.9274 | U17: 0.9314 | V17: 0.9334
B18: PSG | C18: B2 | D18: 0.9532 | E18: 0.9538 | F18: 0.9554 | G18: 0.9488 | H18: 0.9488 | I18: 0.942 | J18: 0.9315 | K18: 0.9397 | L18: 0.934 | M18: 0.9375 | N18: 0.9408 | O18: 0.9301 | P18: 0.919 | Q18: 0.9402 | R18: 0.9453 | S18: 0.9417 | T18: 0.9367 | U18: 0.928 | V18: 0.9267
B19: PSH | C19: B2 | D19: 0.9478 | E19: 0.9336 | F19: 0.9491 | G19: 0.9064 | H19: 0.9356 | I19: 0.9407 | J19: 0.9325 | K19: 0.9353 | L19: 0.9508 | M19: 0.9348 | N19: 0.9316 | O19: 0.9362 | P19: 0.9387 | Q19: 0.9396 | R19: 0.9384 | S19: 0.9445 | T19: 0.9282 | U19: 0.9405 | V19: 0.9221
B20: PSU | C20: B2 | D20: 0.9465 | E20: 0.9588 | F20: 0.951 | G20: 0.9495 | H20: 0.947 | I20: 0.9598 | J20: 0.952 | K20: - | L20: 0.9455 | M20: 0.9348 | N20: 0.8799 | O20: 0.9312 | P20: - | Q20: - | R20: 0.9432 | S20: 0.9532 | T20: 0.9507 | U20: 0.9533 | V20: 0.94
B21: STD | C21: Total | D21: 0.9453 | E21: 0.9453 | F21: 0.9493 | G21: 0.9443 | H21: 0.9481 | I21: 0.9417 | J21: 0.9328 | K21: 0.9346 | L21: 0.9302 | M21: 0.9336 | N21: 0.933 | O21: 0.9194 | P21: 0.9235 | Q21: 0.9364 | R21: 0.9278 | S21: 0.9347 | T21: 0.9325 | U21: 0.9308 | V21: 0.9245
B22: Grand | C22: Total | D22: 0.9404 | E22: 0.9401 | F22: 0.9454 | G22: 0.937 | H22: 0.9385 | I22: 0.9319 | J22: 0.9249 | K22: 0.924 | L22: 0.9225 | M22: 0.9273 | N22: 0.9227 | O22: 0.914 | P22: 0.9179 | Q22: 0.9295 | R22: 0.9203 | S22: 0.9279 | T22: 0.9258 | U22: 0.9239 | V22: 0.9149
